Workbook

Sheet ตารางคำนวน
A1: ท่านสามารถกรอกข้อมูล ตามระยะทางที่ใช้ในแต่ละเดือน จำนวนเวลาถือครองรถ และราคาน้ำมันหรือราคาไฟฟ้า เพื่อใช้ในการวิเคราะห์
C2: ระยะทางวิ่ง | D2: 1500 | E2: ก.ม/เดือน | H2: ราคาน้ำมันดีเซล | I2: 42.2 | J2: บาท/ลิตร
C3: ระยะเวลาถือครอง | D3: 1 | E3: ปี | H3: ราคาน้ำมันเบนซิน | I3: 44.9 | J3: บาท/ลิตร
C4: รวมระยะทางทั้งหมด | D4: =D2*12*D3 -> 18000 | E4: กม | H4: ราคาไฟฟ้า | I4: 4.2 | J4: บาท/หน่วย
A6: ประเภทรถยนต์ | B6: ค่าพลังงาน | C6: ราคาซื้อ | D6: ราคาขายต่อ | E6: ค่าใช้จ่ายสะสม
E7: ภาษี | F7: พรบ | G7: ประกันภัย | H7: ยางรถยนต์ | I7: แบตเตอรี่ | J7: แบตเตอรี่ไฟฟ้า | K7: ค่าซ่อมบำรุง | L7: ค่าพลังงานรวม | M7: ค่าใช้จ่ายสะสมรวม
A8: Toyota Camry Sport | B8: =ค่าพลังงาน!B7 -> 14.5 | C8: =ราคาเริ่มต้น!B5 -> 1475000 | D8: =IF($D$3=1,ราคาเริ่มต้น!D5,IF($D$3=2,ราคาเริ่มต้น!E5,IF($D$3=3,ราคาเริ่มต้น!F5,IF($D$3=4,ราคาเริ่มต้น!G5,IF($D$3=5,ราคาเริ่มต้น!H5,IF($D$3=6,ราคาเริ่มต้น!I5,IF($D$3=7,ราคาเริ่มต้น!J5,IF($D$3=8,ราคาเริ่มต้น!K5,IF($D$3=9,ราคาเริ่มต้น!L5,IF($D$3=10,ราคาเริ่มต้น!M5,IF($D$3=11,ราคาเริ่มต้น!N5,IF($D$3=12,ราคาเริ่มต้น!O5,IF($D$3=13,ราคาเริ่มต้น!P5,IF($D$3=14,ราคาเริ่มต้น!Q5,IF($D$3=15,ราคาเริ่มต้น!R5,IF($D$3=16,ราคาเริ่มต้น!S5,IF($D$3=17,ราคาเริ่มต้น!T5,IF($D$3=18,ราคาเริ่มต้น!U5,IF($D$3=19,ราคาเริ่มต้น!V5,IF($D$3=20,ราคาเริ่มต้น!W5)))))))))))))))))))) -> 1209500 | E8: =IF($D$3=1,ภาษีประจำปี!C5,IF($D$3=2,ภาษีประจำปี!E5,IF($D$3=3,ภาษีประจำปี!F5,IF($D$3=4,ภาษีประจำปี!I5,IF($D$3=5,ภาษีประจำปี!K5,IF($D$3=6,ภาษีประจำปี!M5,IF($D$3=7,ภาษีประจำปี!O5,IF($D$3=8,ภาษีประจำปี!Q5,IF($D$3=9,ภาษีประจำปี!S5,IF($D$3=10,ภาษีประจำปี!U5,IF($D$3=11,ภาษีประจำปี!W5,IF($D$3=12,ภาษีประจำปี!Y5,IF($D$3=13,ภาษีประจำปี!AA5,IF($D$3=14,ภาษีประจำปี!AC5,IF($D$3=15,ภาษีประจำปี!AE5,IF($D$3=16,ภาษีประจำปี!AG5,IF($D$3=17,ภาษีประจำปี!AI5,IF($D$3=18,ภาษีประจำปี!AK5,IF($D$3=19,ภาษีประจำปี!AM5,IF($D$3=20,ภาษีประจำปี!AO5)))))))))))))))))))) -> 3474 | F8: =IF($D$3=1,ประกันภัยบังคับ!B5,IF($D$3=2,ประกันภัยบังคับ!C5,IF($D$3=3,ประกันภัยบังคับ!D5,IF($D$3=4,ประกันภัยบังคับ!E5,IF($D$3=5,ประกันภัยบังคับ!F5,IF($D$3=6,ประกันภัยบังคับ!G5,IF($D$3=7,ประกันภัยบังคับ!H5,IF($D$3=8,ประกันภัยบังคับ!I5,IF($D$3=9,ประกันภัยบังคับ!J5,IF($D$3=10,ประกันภัยบังคับ!K5,IF($D$3=11,ประกันภัยบังคับ!L5,IF($D$3=12,ประกันภัยบังคับ!M5,IF($D$3=13,ประกันภัยบังคับ!N5,IF($D$3=14,ประกันภัยบังคับ!O5,IF($D$3=15,ประกันภัยบังคับ!P5,IF($D$3=16,ประกันภัยบังคับ!Q5,IF($D$3=17,ประกันภัยบังคับ!R5,IF($D$3=18,ประกันภัยบังคับ!S5,IF($D$3=19,ประกันภัยบังคับ!T5,IF($D$3=20,ประกันภัยบังคับ!U5)))))))))))))))))))) -> 645.21 | G8: =IF($D$3=1,ประกันภัยชั้น1!C5,IF($D$3=2,ประกันภัยชั้น1!E5,IF($D$3=3,ประกันภัยชั้น1!G5,IF($D$3=4,ประกันภัยชั้น1!I5,IF($D$3=5,ประกันภัยชั้น1!K5,IF($D$3=6,ประกันภัยชั้น1!M5,IF($D$3=7,ประกันภัยชั้น1!O5,IF($D$3=8,ประกันภัยชั้น1!Q5,IF($D$3=9,ประกันภัยชั้น1!S5,IF($D$3=10,ประกันภัยชั้น1!U5,IF($D$3=11,ประกันภัยชั้น1!W5,IF($D$3=12,ประกันภัยชั้น1!Y5,IF($D$3=13,ประกันภัยชั้น1!AA5,IF($D$3=14,ประกันภัยชั้น1!AC5,IF($D$3=15,ประกันภัยชั้น1!AE5,IF($D$3=16,ประกันภัยชั้น1!AG5,IF($D$3=17,ประกันภัยชั้น1!AI5,IF($D$3=18,ประกันภัยชั้น1!AK5,IF($D$3=19,ประกันภัยชั้น1!AM5,IF($D$3=20,ประกันภัยชั้น1!AO5)))))))))))))))))))) -> 25000 | H8: =IF(AND($D$2<1667,$D$3=1),'ยางรถ (ปี)'!B7,IF(AND($D$2<1667,$D$3=2),'ยางรถ (ปี)'!C7,IF(AND($D$2<1667,$D$3=3),'ยางรถ (ปี)'!D7,IF(AND($D$2<1667,$D$3=4),'ยางรถ (ปี)'!D7,IF(AND($D$2<1667,$D$3=5),'ยางรถ (ปี)'!D7,IF(AND($D$2<1667,$D$3=6),'ยางรถ (ปี)'!G7,IF(AND($D$2<1667,$D$3=7),'ยางรถ (ปี)'!G7,IF(AND($D$2<1667,$D$3=8),'ยางรถ (ปี)'!G7,IF(AND($D$2<1667,$D$3=9),'ยางรถ (ปี)'!J7,IF(AND($D$2<1667,$D$3=10),'ยางรถ (ปี)'!J7,IF(AND($D$2<1667,$D$3=11),'ยางรถ (ปี)'!J7,IF(AND($D$2<1667,$D$3=12),'ยางรถ (ปี)'!M7,IF(AND($D$2<1667,$D$3=13),'ยางรถ (ปี)'!M7,IF(AND($D$2<1667,$D$3=14),'ยางรถ (ปี)'!M7,IF(AND($D$2<1667,$D$3=15),'ยางรถ (ปี)'!P7,IF(AND($D$2<1667,$D$3=16),'ยางรถ (ปี)'!P7,IF(AND($D$2<1667,$D$3=17),'ยางรถ (ปี)'!P7,IF(AND($D$2<1667,$D$3=18),'ยางรถ (ปี)'!S7,IF(AND($D$2<1667,$D$3=19),'ยางรถ (ปี)'!S7,IF(AND($D$2<1667,$D$3=20),'ยางรถ (ปี)'!S7,IF(AND($D$2<1667,$D$3=21),'ยางรถ (ปี)'!V7,IF(AND($D$2>=1667,$D$4<50000),0,IF(AND($D$2>=1667, $D$4<100000),'ยางรถ(ระยะทาง)'!G5,IF(AND($D$2>=1667, $D$4<150000),'ยางรถ(ระยะทาง)'!S6,IF(AND($D$2>=1667, $D$4<200000),'ยางรถ(ระยะทาง)'!S5,IF(AND($D$2>=1667, $D$4<250000),'ยางรถ(ระยะทาง)'!Y5,IF(AND($D$2>=1667, $D$4<300000),'ยางรถ(ระยะทาง)'!AF5,IF(AND($D$2>=1667, $D$4<350000),'ยางรถ(ระยะทาง)'!AL5,IF(AND($D$2>=1667, $D$4<400000),'ยางรถ(ระยะทาง)'!AR5,IF(AND($D$2>=1667, $D$4<450000),'ยางรถ(ระยะทาง)'!AX5,IF(AND($D$2>=1667, $D$4<500000),'ยางรถ(ระยะทาง)'!BD5,IF(AND($D$2>=1667, $D$4<550000),'ยางรถ(ระยะทาง)'!BJ5,IF(AND($D$2>=1667, $D$4<600000),'ยางรถ(ระยะทาง)'!BL5,IF(AND($D$2>=1667, $D$4<650000),'ยางรถ(ระยะทาง)'!BN5,IF(AND($D$2>=1667, $D$4<700000),'ยางรถ(ระยะทาง)'!BP5,IF(AND($D$2>=1667, $D$4<750000),'ยางรถ(ระยะทาง)'!BR5,IF(AND($D$2>=1667, $D$4<800000),'ยางรถ(ระยะทาง)'!BV5))))))))))))))))))))))))))))))))))))) -> 0 | I8: =IF(AND($D$2<1667,$D$3=1),'แบตเตอร์รี่ (ปี)'!B5,IF(AND($D$2<1667,$D$3=2),'แบตเตอร์รี่ (ปี)'!C5,IF(AND($D$2<1667,$D$3=3),'แบตเตอร์รี่ (ปี)'!C5,IF(AND($D$2<1667,$D$3=4),'แบตเตอร์รี่ (ปี)'!E5,IF(AND($D$2<1667,$D$3=5),'แบตเตอร์รี่ (ปี)'!E5,IF(AND($D$2<1667,$D$3=6),'แบตเตอร์รี่ (ปี)'!G5,IF(AND($D$2<1667,$D$3=7),'แบตเตอร์รี่ (ปี)'!G5,IF(AND($D$2<1667,$D$3=8),'แบตเตอร์รี่ (ปี)'!I5,IF(AND($D$2<1667,$D$3=9),'แบตเตอร์รี่ (ปี)'!I5,IF(AND($D$2<1667,$D$3=10),'แบตเตอร์รี่ (ปี)'!K5,IF(AND($D$2<1667,$D$3=11),'แบตเตอร์รี่ (ปี)'!K5,IF(AND($D$2<1667,$D$3=12),'แบตเตอร์รี่ (ปี)'!M5,IF(AND($D$2<1667,$D$3=13),'แบตเตอร์รี่ (ปี)'!M5,IF(AND($D$2<1667,$D$3=14),'แบตเตอร์รี่ (ปี)'!O5,IF(AND($D$2<1667,$D$3=15),'แบตเตอร์รี่ (ปี)'!O5,IF(AND($D$2<1667,$D$3=16),'แบตเตอร์รี่ (ปี)'!Q5,IF(AND($D$2<1667,$D$3=17),'แบตเตอร์รี่ (ปี)'!Q5,IF(AND($D$2<1667,$D$3=18),'แบตเตอร์รี่ (ปี)'!S5,IF(AND($D$2<1667,$D$3=19),'แบตเตอร์รี่ (ปี)'!S5,IF(AND($D$2<1667,$D$3=20),'แบตเตอร์รี่ (ปี)'!U5,IF(AND($D$2>=1667,$D$4<40000),0,IF(AND($D$2>=1667,$D$4<80000),'แบตเตอรี(ระยะทาง) '!E5,IF(AND($D$2>=1667,$D$4<120000),'แบตเตอรี(ระยะทาง) '!I5,IF(AND($D$2>=1667,$D$4<160000),'แบตเตอรี(ระยะทาง) '!M5,IF(AND($D$2>=1667,$D$4<200000),'แบตเตอรี(ระยะทาง) '!Q5,IF(AND($D$2>=1667,$D$4<240000),'แบตเตอรี(ระยะทาง) '!E5,IF(AND($D$2>=1667,$D$4<280000),'แบตเตอรี(ระยะทาง) '!Y5,IF(AND($D$2>=1667,$D$4<320000),'แบตเตอรี(ระยะทาง) '!AC5,IF(AND($D$2>=1667,$D$4<360000),'แบตเตอรี(ระยะทาง) '!AG5,IF(AND($D$2>=1667,$D$4<400000),'แบตเตอรี(ระยะทาง) '!AK5,IF(AND($D$2>=1667,$D$4<440000),'แบตเตอรี(ระยะทาง) '!AO5,IF(AND($D$2>=1667,$D$4<480000),'แบตเตอรี(ระยะทาง) '!AS5,IF(AND($D$2>=1667,$D$4<50000),'แบตเตอรี(ระยะทาง) '!AW5,))))))))))))))))))))))))))))))))) -> 0 | J8: =IF(AND($D$2<1667,$D$3=1),'แบตเตอรีไฟฟ้า (ปี)'!B5,IF(AND($D$2<1667,$D$3=2),'แบตเตอรีไฟฟ้า (ปี)'!C5,IF(AND($D$2<1667,$D$3=3),'แบตเตอรีไฟฟ้า (ปี)'!D5,IF(AND($D$2<1667,$D$3=4),'แบตเตอรีไฟฟ้า (ปี)'!E5,IF(AND($D$2<1667,$D$3=5),'แบตเตอรีไฟฟ้า (ปี)'!F5,IF(AND($D$2<1667,$D$3=6),'แบตเตอรีไฟฟ้า (ปี)'!G5,IF(AND($D$2<1667,$D$3=7),'แบตเตอรีไฟฟ้า (ปี)'!H5,IF(AND($D$2<1667,$D$3=8),'แบตเตอรีไฟฟ้า (ปี)'!I5,IF(AND($D$2<1667,$D$3=9),'แบตเตอรีไฟฟ้า (ปี)'!I5,IF(AND($D$2<1667,$D$3=10),'แบตเตอรีไฟฟ้า (ปี)'!K5,IF(AND($D$2<1667,$D$3=11),'แบตเตอรีไฟฟ้า (ปี)'!I5,IF(AND($D$2<1667,$D$3=12),'แบตเตอรีไฟฟ้า (ปี)'!I5,IF(AND($D$2<1667,$D$3=13),'แบตเตอรีไฟฟ้า (ปี)'!I5,IF(AND($D$2<1667,$D$3=14),'แบตเตอรีไฟฟ้า (ปี)'!I5,IF(AND($D$2<1667,$D$3=15),'แบตเตอรีไฟฟ้า (ปี)'!I5,IF(AND($D$2<1667,$D$3=16),'แบตเตอรีไฟฟ้า (ปี)'!Q5,IF(AND($D$2<1667,$D$3=17),'แบตเตอรีไฟฟ้า (ปี)'!Q5,IF(AND($D$2<1667,$D$3=18),'แบตเตอรีไฟฟ้า (ปี)'!Q5,IF(AND($D$2<1667,$D$3=19),'แบตเตอรีไฟฟ้า (ปี)'!Q5,IF(AND($D$2<1667,$D$3=20),'แบตเตอรีไฟฟ้า (ปี)'!Q5,IF(AND($D$2>=1667,$D$4<170000),0,IF(AND($D$2>=1667,$D$4<340000),'แบตเตอรีรถไฟฟ้า(ระยะทาง)'!R5,IF(AND($D$2>=1667,$D$4<510000),'แบตเตอรีรถไฟฟ้า(ระยะทาง)'!AI5,))))))))))))))))))))))) -> 0 | K8: =IF(AND($D$2<1667,$D$3=1),'ค่าบำรุงรักษา(ปี)'!F5,IF(AND($D$2<1667,$D$3=2),'ค่าบำรุงรักษา(ปี)'!J5,IF(AND($D$2<1667,$D$3=3),'ค่าบำรุงรักษา(ปี)'!N5,IF(AND($D$2<1667,$D$3=4),'ค่าบำรุงรักษา(ปี)'!R5,IF(AND($D$2<1667,$D$3=5),'ค่าบำรุงรักษา(ปี)'!V5,IF(AND($D$2<1667,$D$3=6),'ค่าบำรุงรักษา(ปี)'!Z5,IF(AND($D$2<1667,$D$3=7),'ค่าบำรุงรักษา(ปี)'!AD5,IF(AND($D$2<1667,$D$3=8),'ค่าบำรุงรักษา(ปี)'!AH5,IF(AND($D$2<1667,$D$3=9),'ค่าบำรุงรักษา(ปี)'!AL5,IF(AND($D$2<1667,$D$3=10),'ค่าบำรุงรักษา(ปี)'!AP5,IF(AND($D$2<1667,$D$3=11),'ค่าบำรุงรักษา(ปี)'!AT5,IF(AND($D$2<1667,$D$3=12),'ค่าบำรุงรักษา(ปี)'!AX5,IF(AND($D$2<1667,$D$3=13),'ค่าบำรุงรักษา(ปี)'!BB5,IF(AND($D$2<1667,$D$3=14),'ค่าบำรุงรักษา(ปี)'!BF5,IF(AND($D$2<1667,$D$3=15),'ค่าบำรุงรักษา(ปี)'!BJ5,IF(AND($D$2<1667,$D$3=16),'ค่าบำรุงรักษา(ปี)'!BN5,IF(AND($D$2<1667,$D$3=17),'ค่าบำรุงรักษา(ปี)'!BR5,IF(AND($D$2<1667,$D$3=18),'ค่าบำรุงรักษา(ปี)'!BV5,IF(AND($D$2<1667,$D$3=19),'ค่าบำรุงรักษา(ปี)'!BZ5,IF(AND($D$2<1667,$D$3=20),'ค่าบำรุงรักษา(ปี)'!CD5,IF(AND($D$2>=1667,$D$4<30000),'ค่าบำรุงรักษา (ระยะทาง)'!G5,IF(AND($D$2>=1667,$D$4<40000),'ค่าบำรุงรักษา (ระยะทาง)'!I5,IF(AND($D$2>=1667,$D$4<50000),'ค่าบำรุงรักษา (ระยะทาง)'!K5,IF(AND($D$2>=1667,$D$4<60000),'ค่าบำรุงรักษา (ระยะทาง)'!M5,IF(AND($D$2>=1667,$D$4<70000),'ค่าบำรุงรักษา (ระยะทาง)'!O5,IF(AND($D$2>=1667,$D$4<80000),'ค่าบำรุงรักษา (ระยะทาง)'!Q5,IF(AND($D$2>=1667,$D$4<90000),'ค่าบำรุงรักษา (ระยะทาง)'!S5,IF(AND($D$2>=1667,$D$4<100000),'ค่าบำรุงรักษา (ระยะทาง)'!U5,IF(AND($D$2>=1667,$D$4<110000),'ค่าบำรุงรักษา (ระยะทาง)'!W5,IF(AND($D$2>=1667,$D$4<120000),'ค่าบำรุงรักษา (ระยะทาง)'!Y5,IF(AND($D$2>=1667,$D$4<130000),'ค่าบำรุงรักษา (ระยะทาง)'!AA5,IF(AND($D$2>=1667,$D$4<140000),'ค่าบำรุงรักษา (ระยะทาง)'!AC5,IF(AND($D$2>=1667,$D$4<150000),'ค่าบำรุงรักษา (ระยะทาง)'!AE5,IF(AND($D$2>=1667,$D$4<160000),'ค่าบำรุงรักษา (ระยะทาง)'!AG5,IF(AND($D$2>=1667,$D$4<170000),'ค่าบำรุงรักษา (ระยะทาง)'!AI5,IF(AND($D$2>=1667,$D$4<180000),'ค่าบำรุงรักษา (ระยะทาง)'!AK5,IF(AND($D$2>=1667,$D$4<190000),'ค่าบำรุงรักษา (ระยะทาง)'!AM5,IF(AND($D$2>=1667,$D$4<200000),'ค่าบำรุงรักษา (ระยะทาง)'!AO5,IF(AND($D$2>=1667,$D$4<210000),'ค่าบำรุงรักษา (ระยะทาง)'!AQ5,IF(AND($D$2>=1667,$D$4<220000),'ค่าบำรุงรักษา (ระยะทาง)'!AS5,IF(AND($D$2>=1667,$D$4<220000),'ค่าบำรุงรักษา (ระยะทาง)'!AU5,IF(AND($D$2>=1667,$D$4<240000),'ค่าบำรุงรักษา (ระยะทาง)'!AW5,IF(AND($D$2>=1667,$D$4<250000),'ค่าบำรุงรักษา (ระยะทาง)'!AY5,IF(AND($D$2>=1667,$D$4<260000),'ค่าบำรุงรักษา (ระยะทาง)'!BA5,IF(AND($D$2>=1667,$D$4<270000),'ค่าบำรุงรักษา (ระยะทาง)'!BC5,IF(AND($D$2>=1667,$D$4<280000),'ค่าบำรุงรักษา (ระยะทาง)'!BE5,IF(AND($D$2>=1667,$D$4<290000),'ค่าบำรุงรักษา (ระยะทาง)'!BG5,IF(AND($D$2>=1667,$D$4<300000),'ค่าบำรุงรักษา (ระยะทาง)'!BH3,IF(AND($D$2>=1667,$D$4<310000),'ค่าบำรุงรักษา (ระยะทาง)'!BK5,IF(AND($D$2>=1667,$D$4<320000),'ค่าบำรุงรักษา (ระยะทาง)'!BM5,IF(AND($D$2>=1667,$D$4<330000),'ค่าบำรุงรักษา (ระยะทาง)'!BO5,IF(AND($D$2>=1667,$D$4<340000),'ค่าบำรุงรักษา (ระยะทาง)'!BQ5,IF(AND($D$2>=1667,$D$4<350000),'ค่าบำรุงรักษา (ระยะทาง)'!BS5,IF(AND($D$2>=1667,$D$4<370000),'ค่าบำรุงรักษา (ระยะทาง)'!BW5,IF(AND($D$2>=1667,$D$4<380000),'ค่าบำรุงรักษา (ระยะทาง)'!BY5,IF(AND($D$2>=1667,$D$4<390000),'ค่าบำรุงรักษา (ระยะทาง)'!CA5,IF(AND($D$2>=1667,$D$4<400000),'ค่าบำรุงรักษา (ระยะทาง)'!CC5,IF(AND($D$2>=1667,$D$4<430000),'ค่าบำรุงรักษา (ระยะทาง)'!CI5,IF(AND($D$2>=1667,$D$4<440000),'ค่าบำรุงรักษา (ระยะทาง)'!CK5,IF(AND($D$2>=1667,$D$4<450000),'ค่าบำรุงรักษา (ระยะทาง)'!CM5,IF(AND($D$2>=1667,$D$4<460000),'ค่าบำรุงรักษา (ระยะทาง)'!CO5,IF(AND($D$2>=1667,$D$4<470000),'ค่าบำรุงรักษา (ระยะทาง)'!CQ5,IF(AND($D$2>=1667,$D$4<480000),'ค่าบำรุงรักษา (ระยะทาง)'!CS5,IF(AND($D$2>=1667,$D$4<490000),'ค่าบำรุงรักษา (ระยะทาง)'!CU5)))))))))))))))))))))))))))))))))))))))))))))))))))))))))))))))) -> 6000 | L8: =$D$4*$I$3/B8 -> 55737.931 | M8: =C8+(E8+F8+G8)+(H8+I8)+J8+K8+L8 -> 1565857.1
A9: Altis 1.8G | B9: =ค่าพลังงาน!B8 -> 16.5 | C9: =ราคาเริ่มต้น!B6 -> 909000 | D9: =IF($D$3=1,ราคาเริ่มต้น!D6,IF($D$3=2,ราคาเริ่มต้น!E6,IF($D$3=3,ราคาเริ่มต้น!F6,IF($D$3=4,ราคาเริ่มต้น!G6,IF($D$3=5,ราคาเริ่มต้น!H6,IF($D$3=6,ราคาเริ่มต้น!I6,IF($D$3=7,ราคาเริ่มต้น!J6,IF($D$3=8,ราคาเริ่มต้น!K6,IF($D$3=9,ราคาเริ่มต้น!L6,IF($D$3=10,ราคาเริ่มต้น!M6,IF($D$3=11,ราคาเริ่มต้น!N6,IF($D$3=12,ราคาเริ่มต้น!O6,IF($D$3=13,ราคาเริ่มต้น!P6,IF($D$3=14,ราคาเริ่มต้น!Q6,IF($D$3=15,ราคาเริ่มต้น!R6,IF($D$3=16,ราคาเริ่มต้น!S6,IF($D$3=17,ราคาเริ่มต้น!T6,IF($D$3=18,ราคาเริ่มต้น!U6,IF($D$3=19,ราคาเริ่มต้น!V6,IF($D$3=20,ราคาเริ่มต้น!W6)))))))))))))))))))) -> 772650 | E9: =IF($D$3=1,ภาษีประจำปี!C6,IF($D$3=2,ภาษีประจำปี!E6,IF($D$3=3,ภาษีประจำปี!F6,IF($D$3=4,ภาษีประจำปี!I6,IF($D$3=5,ภาษีประจำปี!K6,IF($D$3=6,ภาษีประจำปี!M6,IF($D$3=7,ภาษีประจำปี!O6,IF($D$3=8,ภาษีประจำปี!Q6,IF($D$3=9,ภาษีประจำปี!S6,IF($D$3=10,ภาษีประจำปี!U6,IF($D$3=11,ภาษีประจำปี!W6,IF($D$3=12,ภาษีประจำปี!Y6,IF($D$3=13,ภาษีประจำปี!AA6,IF($D$3=14,ภาษีประจำปี!AC6,IF($D$3=15,ภาษีประจำปี!AE6,IF($D$3=16,ภาษีประจำปี!AG6,IF($D$3=17,ภาษีประจำปี!AI6,IF($D$3=18,ภาษีประจำปี!AK6,IF($D$3=19,ภาษีประจำปี!AM6,IF($D$3=20,ภาษีประจำปี!AO6)))))))))))))))))))) -> 2250 | F9: =IF($D$3=1,ประกันภัยบังคับ!B6,IF($D$3=2,ประกันภัยบังคับ!C6,IF($D$3=3,ประกันภัยบังคับ!D6,IF($D$3=4,ประกันภัยบังคับ!E6,IF($D$3=5,ประกันภัยบังคับ!F6,IF($D$3=6,ประกันภัยบังคับ!G6,IF($D$3=7,ประกันภัยบังคับ!H6,IF($D$3=8,ประกันภัยบังคับ!I6,IF($D$3=9,ประกันภัยบังคับ!J6,IF($D$3=10,ประกันภัยบังคับ!K6,IF($D$3=11,ประกันภัยบังคับ!L6,IF($D$3=12,ประกันภัยบังคับ!M6,IF($D$3=13,ประกันภัยบังคับ!N6,IF($D$3=14,ประกันภัยบังคับ!O6,IF($D$3=15,ประกันภัยบังคับ!P6,IF($D$3=16,ประกันภัยบังคับ!Q6,IF($D$3=17,ประกันภัยบังคับ!R6,IF($D$3=18,ประกันภัยบังคับ!S6,IF($D$3=19,ประกันภัยบังคับ!T6,IF($D$3=20,ประกันภัยบังคับ!U6)))))))))))))))))))) -> 645.21 | G9: =IF($D$3=1,ประกันภัยชั้น1!C6,IF($D$3=2,ประกันภัยชั้น1!E6,IF($D$3=3,ประกันภัยชั้น1!G6,IF($D$3=4,ประกันภัยชั้น1!I6,IF($D$3=5,ประกันภัยชั้น1!K6,IF($D$3=6,ประกันภัยชั้น1!M6,IF($D$3=7,ประกันภัยชั้น1!O6,IF($D$3=8,ประกันภัยชั้น1!Q6,IF($D$3=9,ประกันภัยชั้น1!S6,IF($D$3=10,ประกันภัยชั้น1!U6,IF($D$3=11,ประกันภัยชั้น1!W6,IF($D$3=12,ประกันภัยชั้น1!Y6,IF($D$3=13,ประกันภัยชั้น1!AA6,IF($D$3=14,ประกันภัยชั้น1!AC6,IF($D$3=15,ประกันภัยชั้น1!AE6,IF($D$3=16,ประกันภัยชั้น1!AG6,IF($D$3=17,ประกันภัยชั้น1!AI6,IF($D$3=18,ประกันภัยชั้น1!AK6,IF($D$3=19,ประกันภัยชั้น1!AM6,IF($D$3=20,ประกันภัยชั้น1!AO6)))))))))))))))))))) -> 22817 | H9: =IF(AND($D$2<1667,$D$3=1),'ยางรถ (ปี)'!B8,IF(AND($D$2<1667,$D$3=2),'ยางรถ (ปี)'!C8,IF(AND($D$2<1667,$D$3=3),'ยางรถ (ปี)'!D8,IF(AND($D$2<1667,$D$3=4),'ยางรถ (ปี)'!D8,IF(AND($D$2<1667,$D$3=5),'ยางรถ (ปี)'!D8,IF(AND($D$2<1667,$D$3=6),'ยางรถ (ปี)'!G8,IF(AND($D$2<1667,$D$3=7),'ยางรถ (ปี)'!G8,IF(AND($D$2<1667,$D$3=8),'ยางรถ (ปี)'!G8,IF(AND($D$2<1667,$D$3=9),'ยางรถ (ปี)'!J8,IF(AND($D$2<1667,$D$3=10),'ยางรถ (ปี)'!J8,IF(AND($D$2<1667,$D$3=11),'ยางรถ (ปี)'!J8,IF(AND($D$2<1667,$D$3=12),'ยางรถ (ปี)'!M8,IF(AND($D$2<1667,$D$3=13),'ยางรถ (ปี)'!M8,IF(AND($D$2<1667,$D$3=14),'ยางรถ (ปี)'!M8,IF(AND($D$2<1667,$D$3=15),'ยางรถ (ปี)'!P8,IF(AND($D$2<1667,$D$3=16),'ยางรถ (ปี)'!P8,IF(AND($D$2<1667,$D$3=17),'ยางรถ (ปี)'!P8,IF(AND($D$2<1667,$D$3=18),'ยางรถ (ปี)'!S8,IF(AND($D$2<1667,$D$3=19),'ยางรถ (ปี)'!S8,IF(AND($D$2<1667,$D$3=20),'ยางรถ (ปี)'!S8,IF(AND($D$2<1667,$D$3=21),'ยางรถ (ปี)'!V8,IF(AND($D$2>=1667,$D$4<50000),0,IF(AND($D$2>=1667, $D$4<100000),'ยางรถ(ระยะทาง)'!G6,IF(AND($D$2>=1667, $D$4<150000),'ยางรถ(ระยะทาง)'!S7,IF(AND($D$2>=1667, $D$4<200000),'ยางรถ(ระยะทาง)'!S6,IF(AND($D$2>=1667, $D$4<250000),'ยางรถ(ระยะทาง)'!Y6,IF(AND($D$2>=1667, $D$4<300000),'ยางรถ(ระยะทาง)'!AF6,IF(AND($D$2>=1667, $D$4<350000),'ยางรถ(ระยะทาง)'!AL6,IF(AND($D$2>=1667, $D$4<400000),'ยางรถ(ระยะทาง)'!AR6,IF(AND($D$2>=1667, $D$4<450000),'ยางรถ(ระยะทาง)'!AX6,IF(AND($D$2>=1667, $D$4<500000),'ยางรถ(ระยะทาง)'!BD6,IF(AND($D$2>=1667, $D$4<550000),'ยางรถ(ระยะทาง)'!BJ6,IF(AND($D$2>=1667, $D$4<600000),'ยางรถ(ระยะทาง)'!BL6,IF(AND($D$2>=1667, $D$4<650000),'ยางรถ(ระยะทาง)'!BN6,IF(AND($D$2>=1667, $D$4<700000),'ยางรถ(ระยะทาง)'!BP6,IF(AND($D$2>=1667, $D$4<750000),'ยางรถ(ระยะทาง)'!BR6,IF(AND($D$2>=1667, $D$4<800000),'ยางรถ(ระยะทาง)'!BV6))))))))))))))))))))))))))))))))))))) -> 0 | I9: =IF(AND($D$2<1667,$D$3=1),'แบตเตอร์รี่ (ปี)'!B6,IF(AND($D$2<1667,$D$3=2),'แบตเตอร์รี่ (ปี)'!C6,IF(AND($D$2<1667,$D$3=3),'แบตเตอร์รี่ (ปี)'!C6,IF(AND($D$2<1667,$D$3=4),'แบตเตอร์รี่ (ปี)'!E6,IF(AND($D$2<1667,$D$3=5),'แบตเตอร์รี่ (ปี)'!E6,IF(AND($D$2<1667,$D$3=6),'แบตเตอร์รี่ (ปี)'!G6,IF(AND($D$2<1667,$D$3=7),'แบตเตอร์รี่ (ปี)'!G6,IF(AND($D$2<1667,$D$3=8),'แบตเตอร์รี่ (ปี)'!I6,IF(AND($D$2<1667,$D$3=9),'แบตเตอร์รี่ (ปี)'!I6,IF(AND($D$2<1667,$D$3=10),'แบตเตอร์รี่ (ปี)'!K6,IF(AND($D$2<1667,$D$3=11),'แบตเตอร์รี่ (ปี)'!K6,IF(AND($D$2<1667,$D$3=12),'แบตเตอร์รี่ (ปี)'!M6,IF(AND($D$2<1667,$D$3=13),'แบตเตอร์รี่ (ปี)'!M6,IF(AND($D$2<1667,$D$3=14),'แบตเตอร์รี่ (ปี)'!O6,IF(AND($D$2<1667,$D$3=15),'แบตเตอร์รี่ (ปี)'!O6,IF(AND($D$2<1667,$D$3=16),'แบตเตอร์รี่ (ปี)'!Q6,IF(AND($D$2<1667,$D$3=17),'แบตเตอร์รี่ (ปี)'!Q6,IF(AND($D$2<1667,$D$3=18),'แบตเตอร์รี่ (ปี)'!S6,IF(AND($D$2<1667,$D$3=19),'แบตเตอร์รี่ (ปี)'!S6,IF(AND($D$2<1667,$D$3=20),'แบตเตอร์รี่ (ปี)'!U6,IF(AND($D$2>=1667,$D$4<40000),0,IF(AND($D$2>=1667,$D$4<80000),'แบตเตอรี(ระยะทาง) '!E6,IF(AND($D$2>=1667,$D$4<120000),'แบตเตอรี(ระยะทาง) '!I6,IF(AND($D$2>=1667,$D$4<160000),'แบตเตอรี(ระยะทาง) '!M6,IF(AND($D$2>=1667,$D$4<200000),'แบตเตอรี(ระยะทาง) '!Q6,IF(AND($D$2>=1667,$D$4<240000),'แบตเตอรี(ระยะทาง) '!E6,IF(AND($D$2>=1667,$D$4<280000),'แบตเตอรี(ระยะทาง) '!Y6,IF(AND($D$2>=1667,$D$4<320000),'แบตเตอรี(ระยะทาง) '!AC6,IF(AND($D$2>=1667,$D$4<360000),'แบตเตอรี(ระยะทาง) '!AG6,IF(AND($D$2>=1667,$D$4<400000),'แบตเตอรี(ระยะทาง) '!AK6,IF(AND($D$2>=1667,$D$4<440000),'แบตเตอรี(ระยะทาง) '!AO6,IF(AND($D$2>=1667,$D$4<480000),'แบตเตอรี(ระยะทาง) '!AS6,IF(AND($D$2>=1667,$D$4<50000),'แบตเตอรี(ระยะทาง) '!AW6,))))))))))))))))))))))))))))))))) -> 0 | J9: =IF(AND($D$2<1667,$D$3=1),'แบตเตอรีไฟฟ้า (ปี)'!B6,IF(AND($D$2<1667,$D$3=2),'แบตเตอรีไฟฟ้า (ปี)'!C6,IF(AND($D$2<1667,$D$3=3),'แบตเตอรีไฟฟ้า (ปี)'!D6,IF(AND($D$2<1667,$D$3=4),'แบตเตอรีไฟฟ้า (ปี)'!E6,IF(AND($D$2<1667,$D$3=5),'แบตเตอรีไฟฟ้า (ปี)'!F6,IF(AND($D$2<1667,$D$3=6),'แบตเตอรีไฟฟ้า (ปี)'!G6,IF(AND($D$2<1667,$D$3=7),'แบตเตอรีไฟฟ้า (ปี)'!H6,IF(AND($D$2<1667,$D$3=8),'แบตเตอรีไฟฟ้า (ปี)'!I6,IF(AND($D$2<1667,$D$3=9),'แบตเตอรีไฟฟ้า (ปี)'!I6,IF(AND($D$2<1667,$D$3=10),'แบตเตอรีไฟฟ้า (ปี)'!K6,IF(AND($D$2<1667,$D$3=11),'แบตเตอรีไฟฟ้า (ปี)'!I6,IF(AND($D$2<1667,$D$3=12),'แบตเตอรีไฟฟ้า (ปี)'!I6,IF(AND($D$2<1667,$D$3=13),'แบตเตอรีไฟฟ้า (ปี)'!I6,IF(AND($D$2<1667,$D$3=14),'แบตเตอรีไฟฟ้า (ปี)'!I6,IF(AND($D$2<1667,$D$3=15),'แบตเตอรีไฟฟ้า (ปี)'!I6,IF(AND($D$2<1667,$D$3=16),'แบตเตอรีไฟฟ้า (ปี)'!Q6,IF(AND($D$2<1667,$D$3=17),'แบตเตอรีไฟฟ้า (ปี)'!Q6,IF(AND($D$2<1667,$D$3=18),'แบตเตอรีไฟฟ้า (ปี)'!Q6,IF(AND($D$2<1667,$D$3=19),'แบตเตอรีไฟฟ้า (ปี)'!Q6,IF(AND($D$2<1667,$D$3=20),'แบตเตอรีไฟฟ้า (ปี)'!Q6,IF(AND($D$2>=1667,$D$4<170000),0,IF(AND($D$2>=1667,$D$4<340000),'แบตเตอรีรถไฟฟ้า(ระยะทาง)'!R6,IF(AND($D$2>=1667,$D$4<510000),'แบตเตอรีรถไฟฟ้า(ระยะทาง)'!AI6,))))))))))))))))))))))) -> 0 | K9: =IF(AND($D$2<1667,$D$3=1),'ค่าบำรุงรักษา(ปี)'!F6,IF(AND($D$2<1667,$D$3=2),'ค่าบำรุงรักษา(ปี)'!J6,IF(AND($D$2<1667,$D$3=3),'ค่าบำรุงรักษา(ปี)'!N6,IF(AND($D$2<1667,$D$3=4),'ค่าบำรุงรักษา(ปี)'!R6,IF(AND($D$2<1667,$D$3=5),'ค่าบำรุงรักษา(ปี)'!V6,IF(AND($D$2<1667,$D$3=6),'ค่าบำรุงรักษา(ปี)'!Z6,IF(AND($D$2<1667,$D$3=7),'ค่าบำรุงรักษา(ปี)'!AD6,IF(AND($D$2<1667,$D$3=8),'ค่าบำรุงรักษา(ปี)'!AH6,IF(AND($D$2<1667,$D$3=9),'ค่าบำรุงรักษา(ปี)'!AL6,IF(AND($D$2<1667,$D$3=10),'ค่าบำรุงรักษา(ปี)'!AP6,IF(AND($D$2<1667,$D$3=11),'ค่าบำรุงรักษา(ปี)'!AT6,IF(AND($D$2<1667,$D$3=12),'ค่าบำรุงรักษา(ปี)'!AX6,IF(AND($D$2<1667,$D$3=13),'ค่าบำรุงรักษา(ปี)'!BB6,IF(AND($D$2<1667,$D$3=14),'ค่าบำรุงรักษา(ปี)'!BF6,IF(AND($D$2<1667,$D$3=15),'ค่าบำรุงรักษา(ปี)'!BJ6,IF(AND($D$2<1667,$D$3=16),'ค่าบำรุงรักษา(ปี)'!BN6,IF(AND($D$2<1667,$D$3=17),'ค่าบำรุงรักษา(ปี)'!BR6,IF(AND($D$2<1667,$D$3=18),'ค่าบำรุงรักษา(ปี)'!BV6,IF(AND($D$2<1667,$D$3=19),'ค่าบำรุงรักษา(ปี)'!BZ6,IF(AND($D$2<1667,$D$3=20),'ค่าบำรุงรักษา(ปี)'!CD6,IF(AND($D$2>=1667,$D$4<30000),'ค่าบำรุงรักษา (ระยะทาง)'!G6,IF(AND($D$2>=1667,$D$4<40000),'ค่าบำรุงรักษา (ระยะทาง)'!I6,IF(AND($D$2>=1667,$D$4<50000),'ค่าบำรุงรักษา (ระยะทาง)'!K6,IF(AND($D$2>=1667,$D$4<60000),'ค่าบำรุงรักษา (ระยะทาง)'!M6,IF(AND($D$2>=1667,$D$4<70000),'ค่าบำรุงรักษา (ระยะทาง)'!O6,IF(AND($D$2>=1667,$D$4<80000),'ค่าบำรุงรักษา (ระยะทาง)'!Q6,IF(AND($D$2>=1667,$D$4<90000),'ค่าบำรุงรักษา (ระยะทาง)'!S6,IF(AND($D$2>=1667,$D$4<100000),'ค่าบำรุงรักษา (ระยะทาง)'!U6,IF(AND($D$2>=1667,$D$4<110000),'ค่าบำรุงรักษา (ระยะทาง)'!W6,IF(AND($D$2>=1667,$D$4<120000),'ค่าบำรุงรักษา (ระยะทาง)'!Y6,IF(AND($D$2>=1667,$D$4<130000),'ค่าบำรุงรักษา (ระยะทาง)'!AA6,IF(AND($D$2>=1667,$D$4<140000),'ค่าบำรุงรักษา (ระยะทาง)'!AC6,IF(AND($D$2>=1667,$D$4<150000),'ค่าบำรุงรักษา (ระยะทาง)'!AE6,IF(AND($D$2>=1667,$D$4<160000),'ค่าบำรุงรักษา (ระยะทาง)'!AG6,IF(AND($D$2>=1667,$D$4<170000),'ค่าบำรุงรักษา (ระยะทาง)'!AI6,IF(AND($D$2>=1667,$D$4<180000),'ค่าบำรุงรักษา (ระยะทาง)'!AK6,IF(AND($D$2>=1667,$D$4<190000),'ค่าบำรุงรักษา (ระยะทาง)'!AM6,IF(AND($D$2>=1667,$D$4<200000),'ค่าบำรุงรักษา (ระยะทาง)'!AO6,IF(AND($D$2>=1667,$D$4<210000),'ค่าบำรุงรักษา (ระยะทาง)'!AQ6,IF(AND($D$2>=1667,$D$4<220000),'ค่าบำรุงรักษา (ระยะทาง)'!AS6,IF(AND($D$2>=1667,$D$4<220000),'ค่าบำรุงรักษา (ระยะทาง)'!AU6,IF(AND($D$2>=1667,$D$4<240000),'ค่าบำรุงรักษา (ระยะทาง)'!AW6,IF(AND($D$2>=1667,$D$4<250000),'ค่าบำรุงรักษา (ระยะทาง)'!AY6,IF(AND($D$2>=1667,$D$4<260000),'ค่าบำรุงรักษา (ระยะทาง)'!BA6,IF(AND($D$2>=1667,$D$4<270000),'ค่าบำรุงรักษา (ระยะทาง)'!BC6,IF(AND($D$2>=1667,$D$4<280000),'ค่าบำรุงรักษา (ระยะทาง)'!BE6,IF(AND($D$2>=1667,$D$4<290000),'ค่าบำรุงรักษา (ระยะทาง)'!BG6,IF(AND($D$2>=1667,$D$4<300000),'ค่าบำรุงรักษา (ระยะทาง)'!BH4,IF(AND($D$2>=1667,$D$4<310000),'ค่าบำรุงรักษา (ระยะทาง)'!BK6,IF(AND($D$2>=1667,$D$4<320000),'ค่าบำรุงรักษา (ระยะทาง)'!BM6,IF(AND($D$2>=1667,$D$4<330000),'ค่าบำรุงรักษา (ระยะทาง)'!BO6,IF(AND($D$2>=1667,$D$4<340000),'ค่าบำรุงรักษา (ระยะทาง)'!BQ6,IF(AND($D$2>=1667,$D$4<350000),'ค่าบำรุงรักษา (ระยะทาง)'!BS6,IF(AND($D$2>=1667,$D$4<370000),'ค่าบำรุงรักษา (ระยะทาง)'!BW6,IF(AND($D$2>=1667,$D$4<380000),'ค่าบำรุงรักษา (ระยะทาง)'!BY6,IF(AND($D$2>=1667,$D$4<390000),'ค่าบำรุงรักษา (ระยะทาง)'!CA6,IF(AND($D$2>=1667,$D$4<400000),'ค่าบำรุงรักษา (ระยะทาง)'!CC6,IF(AND($D$2>=1667,$D$4<430000),'ค่าบำรุงรักษา (ระยะทาง)'!CI6,IF(AND($D$2>=1667,$D$4<440000),'ค่าบำรุงรักษา (ระยะทาง)'!CK6,IF(AND($D$2>=1667,$D$4<450000),'ค่าบำรุงรักษา (ระยะทาง)'!CM6,IF(AND($D$2>=1667,$D$4<460000),'ค่าบำรุงรักษา (ระยะทาง)'!CO6,IF(AND($D$2>=1667,$D$4<470000),'ค่าบำรุงรักษา (ระยะทาง)'!CQ6,IF(AND($D$2>=1667,$D$4<480000),'ค่าบำรุงรักษา (ระยะทาง)'!CS6,IF(AND($D$2>=1667,$D$4<490000),'ค่าบำรุงรักษา (ระยะทาง)'!CU6)))))))))))))))))))))))))))))))))))))))))))))))))))))))))))))))) -> 5000 | L9: =$D$4*$I$3/B9 -> 48981.818 | M9: =C9+(E9+F9+G9)+(H9+I9)+J9+K9+L9 -> 988694.03
A10: Honda Civic | B10: =ค่าพลังงาน!B9 -> 15.5 | C10: =ราคาเริ่มต้น!B7 -> 1039000 | D10: =IF($D$3=1,ราคาเริ่มต้น!D7,IF($D$3=2,ราคาเริ่มต้น!E7,IF($D$3=3,ราคาเริ่มต้น!F7,IF($D$3=4,ราคาเริ่มต้น!G7,IF($D$3=5,ราคาเริ่มต้น!H7,IF($D$3=6,ราคาเริ่มต้น!I7,IF($D$3=7,ราคาเริ่มต้น!J7,IF($D$3=8,ราคาเริ่มต้น!K7,IF($D$3=9,ราคาเริ่มต้น!L7,IF($D$3=10,ราคาเริ่มต้น!M7,IF($D$3=11,ราคาเริ่มต้น!N7,IF($D$3=12,ราคาเริ่มต้น!O7,IF($D$3=13,ราคาเริ่มต้น!P7,IF($D$3=14,ราคาเริ่มต้น!Q7,IF($D$3=15,ราคาเริ่มต้น!R7,IF($D$3=16,ราคาเริ่มต้น!S7,IF($D$3=17,ราคาเริ่มต้น!T7,IF($D$3=18,ราคาเริ่มต้น!U7,IF($D$3=19,ราคาเริ่มต้น!V7,IF($D$3=20,ราคาเริ่มต้น!W7)))))))))))))))))))) -> 862370 | E10: =IF($D$3=1,ภาษีประจำปี!C7,IF($D$3=2,ภาษีประจำปี!E7,IF($D$3=3,ภาษีประจำปี!F7,IF($D$3=4,ภาษีประจำปี!I7,IF($D$3=5,ภาษีประจำปี!K7,IF($D$3=6,ภาษีประจำปี!M7,IF($D$3=7,ภาษีประจำปี!O7,IF($D$3=8,ภาษีประจำปี!Q7,IF($D$3=9,ภาษีประจำปี!S7,IF($D$3=10,ภาษีประจำปี!U7,IF($D$3=11,ภาษีประจำปี!W7,IF($D$3=12,ภาษีประจำปี!Y7,IF($D$3=13,ภาษีประจำปี!AA7,IF($D$3=14,ภาษีประจำปี!AC7,IF($D$3=15,ภาษีประจำปี!AE7,IF($D$3=16,ภาษีประจำปี!AG7,IF($D$3=17,ภาษีประจำปี!AI7,IF($D$3=18,ภาษีประจำปี!AK7,IF($D$3=19,ภาษีประจำปี!AM7,IF($D$3=20,ภาษีประจำปี!AO7)))))))))))))))))))) -> 1647 | F10: =IF($D$3=1,ประกันภัยบังคับ!B7,IF($D$3=2,ประกันภัยบังคับ!C7,IF($D$3=3,ประกันภัยบังคับ!D7,IF($D$3=4,ประกันภัยบังคับ!E7,IF($D$3=5,ประกันภัยบังคับ!F7,IF($D$3=6,ประกันภัยบังคับ!G7,IF($D$3=7,ประกันภัยบังคับ!H7,IF($D$3=8,ประกันภัยบังคับ!I7,IF($D$3=9,ประกันภัยบังคับ!J7,IF($D$3=10,ประกันภัยบังคับ!K7,IF($D$3=11,ประกันภัยบังคับ!L7,IF($D$3=12,ประกันภัยบังคับ!M7,IF($D$3=13,ประกันภัยบังคับ!N7,IF($D$3=14,ประกันภัยบังคับ!O7,IF($D$3=15,ประกันภัยบังคับ!P7,IF($D$3=16,ประกันภัยบังคับ!Q7,IF($D$3=17,ประกันภัยบังคับ!R7,IF($D$3=18,ประกันภัยบังคับ!S7,IF($D$3=19,ประกันภัยบังคับ!T7,IF($D$3=20,ประกันภัยบังคับ!U7)))))))))))))))))))) -> 645.21 | G10: =IF($D$3=1,ประกันภัยชั้น1!C7,IF($D$3=2,ประกันภัยชั้น1!E7,IF($D$3=3,ประกันภัยชั้น1!G7,IF($D$3=4,ประกันภัยชั้น1!I7,IF($D$3=5,ประกันภัยชั้น1!K7,IF($D$3=6,ประกันภัยชั้น1!M7,IF($D$3=7,ประกันภัยชั้น1!O7,IF($D$3=8,ประกันภัยชั้น1!Q7,IF($D$3=9,ประกันภัยชั้น1!S7,IF($D$3=10,ประกันภัยชั้น1!U7,IF($D$3=11,ประกันภัยชั้น1!W7,IF($D$3=12,ประกันภัยชั้น1!Y7,IF($D$3=13,ประกันภัยชั้น1!AA7,IF($D$3=14,ประกันภัยชั้น1!AC7,IF($D$3=15,ประกันภัยชั้น1!AE7,IF($D$3=16,ประกันภัยชั้น1!AG7,IF($D$3=17,ประกันภัยชั้น1!AI7,IF($D$3=18,ประกันภัยชั้น1!AK7,IF($D$3=19,ประกันภัยชั้น1!AM7,IF($D$3=20,ประกันภัยชั้น1!AO7)))))))))))))))))))) -> 24500 | H10: =IF(AND($D$2<1667,$D$3=1),'ยางรถ (ปี)'!B9,IF(AND($D$2<1667,$D$3=2),'ยางรถ (ปี)'!C9,IF(AND($D$2<1667,$D$3=3),'ยางรถ (ปี)'!D9,IF(AND($D$2<1667,$D$3=4),'ยางรถ (ปี)'!D9,IF(AND($D$2<1667,$D$3=5),'ยางรถ (ปี)'!D9,IF(AND($D$2<1667,$D$3=6),'ยางรถ (ปี)'!G9,IF(AND($D$2<1667,$D$3=7),'ยางรถ (ปี)'!G9,IF(AND($D$2<1667,$D$3=8),'ยางรถ (ปี)'!G9,IF(AND($D$2<1667,$D$3=9),'ยางรถ (ปี)'!J9,IF(AND($D$2<1667,$D$3=10),'ยางรถ (ปี)'!J9,IF(AND($D$2<1667,$D$3=11),'ยางรถ (ปี)'!J9,IF(AND($D$2<1667,$D$3=12),'ยางรถ (ปี)'!M9,IF(AND($D$2<1667,$D$3=13),'ยางรถ (ปี)'!M9,IF(AND($D$2<1667,$D$3=14),'ยางรถ (ปี)'!M9,IF(AND($D$2<1667,$D$3=15),'ยางรถ (ปี)'!P9,IF(AND($D$2<1667,$D$3=16),'ยางรถ (ปี)'!P9,IF(AND($D$2<1667,$D$3=17),'ยางรถ (ปี)'!P9,IF(AND($D$2<1667,$D$3=18),'ยางรถ (ปี)'!S9,IF(AND($D$2<1667,$D$3=19),'ยางรถ (ปี)'!S9,IF(AND($D$2<1667,$D$3=20),'ยางรถ (ปี)'!S9,IF(AND($D$2<1667,$D$3=21),'ยางรถ (ปี)'!V9,IF(AND($D$2>=1667,$D$4<50000),0,IF(AND($D$2>=1667, $D$4<100000),'ยางรถ(ระยะทาง)'!G7,IF(AND($D$2>=1667, $D$4<150000),'ยางรถ(ระยะทาง)'!M7,IF(AND($D$2>=1667, $D$4<200000),'ยางรถ(ระยะทาง)'!S7,IF(AND($D$2>=1667, $D$4<250000),'ยางรถ(ระยะทาง)'!Y7,IF(AND($D$2>=1667, $D$4<300000),'ยางรถ(ระยะทาง)'!AF7,IF(AND($D$2>=1667, $D$4<350000),'ยางรถ(ระยะทาง)'!AL7,IF(AND($D$2>=1667, $D$4<400000),'ยางรถ(ระยะทาง)'!AR7,IF(AND($D$2>=1667, $D$4<450000),'ยางรถ(ระยะทาง)'!AX7,IF(AND($D$2>=1667, $D$4<500000),'ยางรถ(ระยะทาง)'!BD7,IF(AND($D$2>=1667, $D$4<550000),'ยางรถ(ระยะทาง)'!BJ7,IF(AND($D$2>=1667, $D$4<600000),'ยางรถ(ระยะทาง)'!BL7,IF(AND($D$2>=1667, $D$4<650000),'ยางรถ(ระยะทาง)'!BN7,IF(AND($D$2>=1667, $D$4<700000),'ยางรถ(ระยะทาง)'!BP7,IF(AND($D$2>=1667, $D$4<750000),'ยางรถ(ระยะทาง)'!BR7,IF(AND($D$2>=1667, $D$4<800000),'ยางรถ(ระยะทาง)'!BV7))))))))))))))))))))))))))))))))))))) -> 0 | I10: =IF(AND($D$2<1667,$D$3=1),'แบตเตอร์รี่ (ปี)'!B7,IF(AND($D$2<1667,$D$3=2),'แบตเตอร์รี่ (ปี)'!C7,IF(AND($D$2<1667,$D$3=3),'แบตเตอร์รี่ (ปี)'!C7,IF(AND($D$2<1667,$D$3=4),'แบตเตอร์รี่ (ปี)'!E7,IF(AND($D$2<1667,$D$3=5),'แบตเตอร์รี่ (ปี)'!E7,IF(AND($D$2<1667,$D$3=6),'แบตเตอร์รี่ (ปี)'!G7,IF(AND($D$2<1667,$D$3=7),'แบตเตอร์รี่ (ปี)'!G7,IF(AND($D$2<1667,$D$3=8),'แบตเตอร์รี่ (ปี)'!I7,IF(AND($D$2<1667,$D$3=9),'แบตเตอร์รี่ (ปี)'!I7,IF(AND($D$2<1667,$D$3=10),'แบตเตอร์รี่ (ปี)'!K7,IF(AND($D$2<1667,$D$3=11),'แบตเตอร์รี่ (ปี)'!K7,IF(AND($D$2<1667,$D$3=12),'แบตเตอร์รี่ (ปี)'!M7,IF(AND($D$2<1667,$D$3=13),'แบตเตอร์รี่ (ปี)'!M7,IF(AND($D$2<1667,$D$3=14),'แบตเตอร์รี่ (ปี)'!O7,IF(AND($D$2<1667,$D$3=15),'แบตเตอร์รี่ (ปี)'!O7,IF(AND($D$2<1667,$D$3=16),'แบตเตอร์รี่ (ปี)'!Q7,IF(AND($D$2<1667,$D$3=17),'แบตเตอร์รี่ (ปี)'!Q7,IF(AND($D$2<1667,$D$3=18),'แบตเตอร์รี่ (ปี)'!S7,IF(AND($D$2<1667,$D$3=19),'แบตเตอร์รี่ (ปี)'!S7,IF(AND($D$2<1667,$D$3=20),'แบตเตอร์รี่ (ปี)'!U7,IF(AND($D$2>=1667,$D$4<40000),0,IF(AND($D$2>=1667,$D$4<80000),'แบตเตอรี(ระยะทาง) '!E7,IF(AND($D$2>=1667,$D$4<120000),'แบตเตอรี(ระยะทาง) '!I7,IF(AND($D$2>=1667,$D$4<160000),'แบตเตอรี(ระยะทาง) '!M7,IF(AND($D$2>=1667,$D$4<200000),'แบตเตอรี(ระยะทาง) '!Q7,IF(AND($D$2>=1667,$D$4<240000),'แบตเตอรี(ระยะทาง) '!E7,IF(AND($D$2>=1667,$D$4<280000),'แบตเตอรี(ระยะทาง) '!Y7,IF(AND($D$2>=1667,$D$4<320000),'แบตเตอรี(ระยะทาง) '!AC7,IF(AND($D$2>=1667,$D$4<360000),'แบตเตอรี(ระยะทาง) '!AG7,IF(AND($D$2>=1667,$D$4<400000),'แบตเตอรี(ระยะทาง) '!AK7,IF(AND($D$2>=1667,$D$4<440000),'แบตเตอรี(ระยะทาง) '!AO7,IF(AND($D$2>=1667,$D$4<480000),'แบตเตอรี(ระยะทาง) '!AS7,IF(AND($D$2>=1667,$D$4<50000),'แบตเตอรี(ระยะทาง) '!AW7,))))))))))))))))))))))))))))))))) -> 0 | J10: =IF(AND($D$2<1667,$D$3=1),'แบตเตอรีไฟฟ้า (ปี)'!B7,IF(AND($D$2<1667,$D$3=2),'แบตเตอรีไฟฟ้า (ปี)'!C7,IF(AND($D$2<1667,$D$3=3),'แบตเตอรีไฟฟ้า (ปี)'!D7,IF(AND($D$2<1667,$D$3=4),'แบตเตอรีไฟฟ้า (ปี)'!E7,IF(AND($D$2<1667,$D$3=5),'แบตเตอรีไฟฟ้า (ปี)'!F7,IF(AND($D$2<1667,$D$3=6),'แบตเตอรีไฟฟ้า (ปี)'!G7,IF(AND($D$2<1667,$D$3=7),'แบตเตอรีไฟฟ้า (ปี)'!H7,IF(AND($D$2<1667,$D$3=8),'แบตเตอรีไฟฟ้า (ปี)'!I7,IF(AND($D$2<1667,$D$3=9),'แบตเตอรีไฟฟ้า (ปี)'!I7,IF(AND($D$2<1667,$D$3=10),'แบตเตอรีไฟฟ้า (ปี)'!K7,IF(AND($D$2<1667,$D$3=11),'แบตเตอรีไฟฟ้า (ปี)'!I7,IF(AND($D$2<1667,$D$3=12),'แบตเตอรีไฟฟ้า (ปี)'!I7,IF(AND($D$2<1667,$D$3=13),'แบตเตอรีไฟฟ้า (ปี)'!I7,IF(AND($D$2<1667,$D$3=14),'แบตเตอรีไฟฟ้า (ปี)'!I7,IF(AND($D$2<1667,$D$3=15),'แบตเตอรีไฟฟ้า (ปี)'!I7,IF(AND($D$2<1667,$D$3=16),'แบตเตอรีไฟฟ้า (ปี)'!Q7,IF(AND($D$2<1667,$D$3=17),'แบตเตอรีไฟฟ้า (ปี)'!Q7,IF(AND($D$2<1667,$D$3=18),'แบตเตอรีไฟฟ้า (ปี)'!Q7,IF(AND($D$2<1667,$D$3=19),'แบตเตอรีไฟฟ้า (ปี)'!Q7,IF(AND($D$2<1667,$D$3=20),'แบตเตอรีไฟฟ้า (ปี)'!Q7,IF(AND($D$2>=1667,$D$4<170000),0,IF(AND($D$2>=1667,$D$4<340000),'แบตเตอรีรถไฟฟ้า(ระยะทาง)'!R7,IF(AND($D$2>=1667,$D$4<510000),'แบตเตอรีรถไฟฟ้า(ระยะทาง)'!AI7,))))))))))))))))))))))) -> 0 | K10: =IF(AND($D$2<1667,$D$3=1),'ค่าบำรุงรักษา(ปี)'!F7,IF(AND($D$2<1667,$D$3=2),'ค่าบำรุงรักษา(ปี)'!J7,IF(AND($D$2<1667,$D$3=3),'ค่าบำรุงรักษา(ปี)'!N7,IF(AND($D$2<1667,$D$3=4),'ค่าบำรุงรักษา(ปี)'!R7,IF(AND($D$2<1667,$D$3=5),'ค่าบำรุงรักษา(ปี)'!V7,IF(AND($D$2<1667,$D$3=6),'ค่าบำรุงรักษา(ปี)'!Z7,IF(AND($D$2<1667,$D$3=7),'ค่าบำรุงรักษา(ปี)'!AD7,IF(AND($D$2<1667,$D$3=8),'ค่าบำรุงรักษา(ปี)'!AH7,IF(AND($D$2<1667,$D$3=9),'ค่าบำรุงรักษา(ปี)'!AL7,IF(AND($D$2<1667,$D$3=10),'ค่าบำรุงรักษา(ปี)'!AP7,IF(AND($D$2<1667,$D$3=11),'ค่าบำรุงรักษา(ปี)'!AT7,IF(AND($D$2<1667,$D$3=12),'ค่าบำรุงรักษา(ปี)'!AX7,IF(AND($D$2<1667,$D$3=13),'ค่าบำรุงรักษา(ปี)'!BB7,IF(AND($D$2<1667,$D$3=14),'ค่าบำรุงรักษา(ปี)'!BF7,IF(AND($D$2<1667,$D$3=15),'ค่าบำรุงรักษา(ปี)'!BJ7,IF(AND($D$2<1667,$D$3=16),'ค่าบำรุงรักษา(ปี)'!BN7,IF(AND($D$2<1667,$D$3=17),'ค่าบำรุงรักษา(ปี)'!BR7,IF(AND($D$2<1667,$D$3=18),'ค่าบำรุงรักษา(ปี)'!BV7,IF(AND($D$2<1667,$D$3=19),'ค่าบำรุงรักษา(ปี)'!BZ7,IF(AND($D$2<1667,$D$3=20),'ค่าบำรุงรักษา(ปี)'!CD7,IF(AND($D$2>=1667,$D$4<30000),'ค่าบำรุงรักษา (ระยะทาง)'!G7,IF(AND($D$2>=1667,$D$4<40000),'ค่าบำรุงรักษา (ระยะทาง)'!I7,IF(AND($D$2>=1667,$D$4<50000),'ค่าบำรุงรักษา (ระยะทาง)'!K7,IF(AND($D$2>=1667,$D$4<60000),'ค่าบำรุงรักษา (ระยะทาง)'!M7,IF(AND($D$2>=1667,$D$4<70000),'ค่าบำรุงรักษา (ระยะทาง)'!O7,IF(AND($D$2>=1667,$D$4<80000),'ค่าบำรุงรักษา (ระยะทาง)'!Q7,IF(AND($D$2>=1667,$D$4<90000),'ค่าบำรุงรักษา (ระยะทาง)'!S7,IF(AND($D$2>=1667,$D$4<100000),'ค่าบำรุงรักษา (ระยะทาง)'!U7,IF(AND($D$2>=1667,$D$4<110000),'ค่าบำรุงรักษา (ระยะทาง)'!W7,IF(AND($D$2>=1667,$D$4<120000),'ค่าบำรุงรักษา (ระยะทาง)'!Y7,IF(AND($D$2>=1667,$D$4<130000),'ค่าบำรุงรักษา (ระยะทาง)'!AA7,IF(AND($D$2>=1667,$D$4<140000),'ค่าบำรุงรักษา (ระยะทาง)'!AC7,IF(AND($D$2>=1667,$D$4<150000),'ค่าบำรุงรักษา (ระยะทาง)'!AE7,IF(AND($D$2>=1667,$D$4<160000),'ค่าบำรุงรักษา (ระยะทาง)'!AG7,IF(AND($D$2>=1667,$D$4<170000),'ค่าบำรุงรักษา (ระยะทาง)'!AI7,IF(AND($D$2>=1667,$D$4<180000),'ค่าบำรุงรักษา (ระยะทาง)'!AK7,IF(AND($D$2>=1667,$D$4<190000),'ค่าบำรุงรักษา (ระยะทาง)'!AM7,IF(AND($D$2>=1667,$D$4<200000),'ค่าบำรุงรักษา (ระยะทาง)'!AO7,IF(AND($D$2>=1667,$D$4<210000),'ค่าบำรุงรักษา (ระยะทาง)'!AQ7,IF(AND($D$2>=1667,$D$4<220000),'ค่าบำรุงรักษา (ระยะทาง)'!AS7,IF(AND($D$2>=1667,$D$4<220000),'ค่าบำรุงรักษา (ระยะทาง)'!AU7,IF(AND($D$2>=1667,$D$4<240000),'ค่าบำรุงรักษา (ระยะทาง)'!AW7,IF(AND($D$2>=1667,$D$4<250000),'ค่าบำรุงรักษา (ระยะทาง)'!AY7,IF(AND($D$2>=1667,$D$4<260000),'ค่าบำรุงรักษา (ระยะทาง)'!BA7,IF(AND($D$2>=1667,$D$4<270000),'ค่าบำรุงรักษา (ระยะทาง)'!BC7,IF(AND($D$2>=1667,$D$4<280000),'ค่าบำรุงรักษา (ระยะทาง)'!BE7,IF(AND($D$2>=1667,$D$4<290000),'ค่าบำรุงรักษา (ระยะทาง)'!BG7,IF(AND($D$2>=1667,$D$4<300000),'ค่าบำรุงรักษา (ระยะทาง)'!BH5,IF(AND($D$2>=1667,$D$4<310000),'ค่าบำรุงรักษา (ระยะทาง)'!BK7,IF(AND($D$2>=1667,$D$4<320000),'ค่าบำรุงรักษา (ระยะทาง)'!BM7,IF(AND($D$2>=1667,$D$4<330000),'ค่าบำรุงรักษา (ระยะทาง)'!BO7,IF(AND($D$2>=1667,$D$4<340000),'ค่าบำรุงรักษา (ระยะทาง)'!BQ7,IF(AND($D$2>=1667,$D$4<350000),'ค่าบำรุงรักษา (ระยะทาง)'!BS7,IF(AND($D$2>=1667,$D$4<370000),'ค่าบำรุงรักษา (ระยะทาง)'!BW7,IF(AND($D$2>=1667,$D$4<380000),'ค่าบำรุงรักษา (ระยะทาง)'!BY7,IF(AND($D$2>=1667,$D$4<390000),'ค่าบำรุงรักษา (ระยะทาง)'!CA7,IF(AND($D$2>=1667,$D$4<400000),'ค่าบำรุงรักษา (ระยะทาง)'!CC7,IF(AND($D$2>=1667,$D$4<430000),'ค่าบำรุงรักษา (ระยะทาง)'!CI7,IF(AND($D$2>=1667,$D$4<440000),'ค่าบำรุงรักษา (ระยะทาง)'!CK7,IF(AND($D$2>=1667,$D$4<450000),'ค่าบำรุงรักษา (ระยะทาง)'!CM7,IF(AND($D$2>=1667,$D$4<460000),'ค่าบำรุงรักษา (ระยะทาง)'!CO7,IF(AND($D$2>=1667,$D$4<470000),'ค่าบำรุงรักษา (ระยะทาง)'!CQ7,IF(AND($D$2>=1667,$D$4<480000),'ค่าบำรุงรักษา (ระยะทาง)'!CS7,IF(AND($D$2>=1667,$D$4<490000),'ค่าบำรุงรักษา (ระยะทาง)'!CU7)))))))))))))))))))))))))))))))))))))))))))))))))))))))))))))))) -> 5500 | L10: =$D$4*$I$3/B10 -> 52141.935 | M10: =C10+(E10+F10+G10)+(H10+I10)+J10+K10+L10 -> 1123434.1
A11: Masda3 | B11: =ค่าพลังงาน!B10 -> 15 | C11: =ราคาเริ่มต้น!B8 -> 1198000 | D11: =IF($D$3=1,ราคาเริ่มต้น!D8,IF($D$3=2,ราคาเริ่มต้น!E8,IF($D$3=3,ราคาเริ่มต้น!F8,IF($D$3=4,ราคาเริ่มต้น!G8,IF($D$3=5,ราคาเริ่มต้น!H8,IF($D$3=6,ราคาเริ่มต้น!I8,IF($D$3=7,ราคาเริ่มต้น!J8,IF($D$3=8,ราคาเริ่มต้น!K8,IF($D$3=9,ราคาเริ่มต้น!L8,IF($D$3=10,ราคาเริ่มต้น!M8,IF($D$3=11,ราคาเริ่มต้น!N8,IF($D$3=12,ราคาเริ่มต้น!O8,IF($D$3=13,ราคาเริ่มต้น!P8,IF($D$3=14,ราคาเริ่มต้น!Q8,IF($D$3=15,ราคาเริ่มต้น!R8,IF($D$3=16,ราคาเริ่มต้น!S8,IF($D$3=17,ราคาเริ่มต้น!T8,IF($D$3=18,ราคาเริ่มต้น!U8,IF($D$3=19,ราคาเริ่มต้น!V8,IF($D$3=20,ราคาเริ่มต้น!W8)))))))))))))))))))) -> 1018300 | E11: =IF($D$3=1,ภาษีประจำปี!C8,IF($D$3=2,ภาษีประจำปี!E8,IF($D$3=3,ภาษีประจำปี!F8,IF($D$3=4,ภาษีประจำปี!I8,IF($D$3=5,ภาษีประจำปี!K8,IF($D$3=6,ภาษีประจำปี!M8,IF($D$3=7,ภาษีประจำปี!O8,IF($D$3=8,ภาษีประจำปี!Q8,IF($D$3=9,ภาษีประจำปี!S8,IF($D$3=10,ภาษีประจำปี!U8,IF($D$3=11,ภาษีประจำปี!W8,IF($D$3=12,ภาษีประจำปี!Y8,IF($D$3=13,ภาษีประจำปี!AA8,IF($D$3=14,ภาษีประจำปี!AC8,IF($D$3=15,ภาษีประจำปี!AE8,IF($D$3=16,ภาษีประจำปี!AG8,IF($D$3=17,ภาษีประจำปี!AI8,IF($D$3=18,ภาษีประจำปี!AK8,IF($D$3=19,ภาษีประจำปี!AM8,IF($D$3=20,ภาษีประจำปี!AO8)))))))))))))))))))) -> 2900 | F11: =IF($D$3=1,ประกันภัยบังคับ!B8,IF($D$3=2,ประกันภัยบังคับ!C8,IF($D$3=3,ประกันภัยบังคับ!D8,IF($D$3=4,ประกันภัยบังคับ!E8,IF($D$3=5,ประกันภัยบังคับ!F8,IF($D$3=6,ประกันภัยบังคับ!G8,IF($D$3=7,ประกันภัยบังคับ!H8,IF($D$3=8,ประกันภัยบังคับ!I8,IF($D$3=9,ประกันภัยบังคับ!J8,IF($D$3=10,ประกันภัยบังคับ!K8,IF($D$3=11,ประกันภัยบังคับ!L8,IF($D$3=12,ประกันภัยบังคับ!M8,IF($D$3=13,ประกันภัยบังคับ!N8,IF($D$3=14,ประกันภัยบังคับ!O8,IF($D$3=15,ประกันภัยบังคับ!P8,IF($D$3=16,ประกันภัยบังคับ!Q8,IF($D$3=17,ประกันภัยบังคับ!R8,IF($D$3=18,ประกันภัยบังคับ!S8,IF($D$3=19,ประกันภัยบังคับ!T8,IF($D$3=20,ประกันภัยบังคับ!U8)))))))))))))))))))) -> 645.21 | G11: =IF($D$3=1,ประกันภัยชั้น1!C8,IF($D$3=2,ประกันภัยชั้น1!E8,IF($D$3=3,ประกันภัยชั้น1!G8,IF($D$3=4,ประกันภัยชั้น1!I8,IF($D$3=5,ประกันภัยชั้น1!K8,IF($D$3=6,ประกันภัยชั้น1!M8,IF($D$3=7,ประกันภัยชั้น1!O8,IF($D$3=8,ประกันภัยชั้น1!Q8,IF($D$3=9,ประกันภัยชั้น1!S8,IF($D$3=10,ประกันภัยชั้น1!U8,IF($D$3=11,ประกันภัยชั้น1!W8,IF($D$3=12,ประกันภัยชั้น1!Y8,IF($D$3=13,ประกันภัยชั้น1!AA8,IF($D$3=14,ประกันภัยชั้น1!AC8,IF($D$3=15,ประกันภัยชั้น1!AE8,IF($D$3=16,ประกันภัยชั้น1!AG8,IF($D$3=17,ประกันภัยชั้น1!AI8,IF($D$3=18,ประกันภัยชั้น1!AK8,IF($D$3=19,ประกันภัยชั้น1!AM8,IF($D$3=20,ประกันภัยชั้น1!AO8)))))))))))))))))))) -> 26645 | H11: =IF(AND($D$2<1667,$D$3=1),'ยางรถ (ปี)'!B10,IF(AND($D$2<1667,$D$3=2),'ยางรถ (ปี)'!C10,IF(AND($D$2<1667,$D$3=3),'ยางรถ (ปี)'!D10,IF(AND($D$2<1667,$D$3=4),'ยางรถ (ปี)'!D10,IF(AND($D$2<1667,$D$3=5),'ยางรถ (ปี)'!D10,IF(AND($D$2<1667,$D$3=6),'ยางรถ (ปี)'!G10,IF(AND($D$2<1667,$D$3=7),'ยางรถ (ปี)'!G10,IF(AND($D$2<1667,$D$3=8),'ยางรถ (ปี)'!G10,IF(AND($D$2<1667,$D$3=9),'ยางรถ (ปี)'!J10,IF(AND($D$2<1667,$D$3=10),'ยางรถ (ปี)'!J10,IF(AND($D$2<1667,$D$3=11),'ยางรถ (ปี)'!J10,IF(AND($D$2<1667,$D$3=12),'ยางรถ (ปี)'!M10,IF(AND($D$2<1667,$D$3=13),'ยางรถ (ปี)'!M10,IF(AND($D$2<1667,$D$3=14),'ยางรถ (ปี)'!M10,IF(AND($D$2<1667,$D$3=15),'ยางรถ (ปี)'!P10,IF(AND($D$2<1667,$D$3=16),'ยางรถ (ปี)'!P10,IF(AND($D$2<1667,$D$3=17),'ยางรถ (ปี)'!P10,IF(AND($D$2<1667,$D$3=18),'ยางรถ (ปี)'!S10,IF(AND($D$2<1667,$D$3=19),'ยางรถ (ปี)'!S10,IF(AND($D$2<1667,$D$3=20),'ยางรถ (ปี)'!S10,IF(AND($D$2<1667,$D$3=21),'ยางรถ (ปี)'!V10,IF(AND($D$2>=1667,$D$4<50000),0,IF(AND($D$2>=1667, $D$4<100000),'ยางรถ(ระยะทาง)'!G8,IF(AND($D$2>=1667, $D$4<150000),'ยางรถ(ระยะทาง)'!M8,IF(AND($D$2>=1667, $D$4<200000),'ยางรถ(ระยะทาง)'!S8,IF(AND($D$2>=1667, $D$4<250000),'ยางรถ(ระยะทาง)'!Y8,IF(AND($D$2>=1667, $D$4<300000),'ยางรถ(ระยะทาง)'!AF8,IF(AND($D$2>=1667, $D$4<350000),'ยางรถ(ระยะทาง)'!AL8,IF(AND($D$2>=1667, $D$4<400000),'ยางรถ(ระยะทาง)'!AR8,IF(AND($D$2>=1667, $D$4<450000),'ยางรถ(ระยะทาง)'!AX8,IF(AND($D$2>=1667, $D$4<500000),'ยางรถ(ระยะทาง)'!BD8,IF(AND($D$2>=1667, $D$4<550000),'ยางรถ(ระยะทาง)'!BJ8,IF(AND($D$2>=1667, $D$4<600000),'ยางรถ(ระยะทาง)'!BL8,IF(AND($D$2>=1667, $D$4<650000),'ยางรถ(ระยะทาง)'!BN8,IF(AND($D$2>=1667, $D$4<700000),'ยางรถ(ระยะทาง)'!BP8,IF(AND($D$2>=1667, $D$4<750000),'ยางรถ(ระยะทาง)'!BR8,IF(AND($D$2>=1667, $D$4<800000),'ยางรถ(ระยะทาง)'!BV8))))))))))))))))))))))))))))))))))))) -> 0 | I11: =IF(AND($D$2<1667,$D$3=1),'แบตเตอร์รี่ (ปี)'!B8,IF(AND($D$2<1667,$D$3=2),'แบตเตอร์รี่ (ปี)'!C8,IF(AND($D$2<1667,$D$3=3),'แบตเตอร์รี่ (ปี)'!C8,IF(AND($D$2<1667,$D$3=4),'แบตเตอร์รี่ (ปี)'!E8,IF(AND($D$2<1667,$D$3=5),'แบตเตอร์รี่ (ปี)'!E8,IF(AND($D$2<1667,$D$3=6),'แบตเตอร์รี่ (ปี)'!G8,IF(AND($D$2<1667,$D$3=7),'แบตเตอร์รี่ (ปี)'!G8,IF(AND($D$2<1667,$D$3=8),'แบตเตอร์รี่ (ปี)'!I8,IF(AND($D$2<1667,$D$3=9),'แบตเตอร์รี่ (ปี)'!I8,IF(AND($D$2<1667,$D$3=10),'แบตเตอร์รี่ (ปี)'!K8,IF(AND($D$2<1667,$D$3=11),'แบตเตอร์รี่ (ปี)'!K8,IF(AND($D$2<1667,$D$3=12),'แบตเตอร์รี่ (ปี)'!M8,IF(AND($D$2<1667,$D$3=13),'แบตเตอร์รี่ (ปี)'!M8,IF(AND($D$2<1667,$D$3=14),'แบตเตอร์รี่ (ปี)'!O8,IF(AND($D$2<1667,$D$3=15),'แบตเตอร์รี่ (ปี)'!O8,IF(AND($D$2<1667,$D$3=16),'แบตเตอร์รี่ (ปี)'!Q8,IF(AND($D$2<1667,$D$3=17),'แบตเตอร์รี่ (ปี)'!Q8,IF(AND($D$2<1667,$D$3=18),'แบตเตอร์รี่ (ปี)'!S8,IF(AND($D$2<1667,$D$3=19),'แบตเตอร์รี่ (ปี)'!S8,IF(AND($D$2<1667,$D$3=20),'แบตเตอร์รี่ (ปี)'!U8,IF(AND($D$2>=1667,$D$4<40000),0,IF(AND($D$2>=1667,$D$4<80000),'แบตเตอรี(ระยะทาง) '!E8,IF(AND($D$2>=1667,$D$4<120000),'แบตเตอรี(ระยะทาง) '!I8,IF(AND($D$2>=1667,$D$4<160000),'แบตเตอรี(ระยะทาง) '!M8,IF(AND($D$2>=1667,$D$4<200000),'แบตเตอรี(ระยะทาง) '!Q8,IF(AND($D$2>=1667,$D$4<240000),'แบตเตอรี(ระยะทาง) '!E8,IF(AND($D$2>=1667,$D$4<280000),'แบตเตอรี(ระยะทาง) '!Y8,IF(AND($D$2>=1667,$D$4<320000),'แบตเตอรี(ระยะทาง) '!AC8,IF(AND($D$2>=1667,$D$4<360000),'แบตเตอรี(ระยะทาง) '!AG8,IF(AND($D$2>=1667,$D$4<400000),'แบตเตอรี(ระยะทาง) '!AK8,IF(AND($D$2>=1667,$D$4<440000),'แบตเตอรี(ระยะทาง) '!AO8,IF(AND($D$2>=1667,$D$4<480000),'แบตเตอรี(ระยะทาง) '!AS8,IF(AND($D$2>=1667,$D$4<50000),'แบตเตอรี(ระยะทาง) '!AW8,))))))))))))))))))))))))))))))))) -> 0 | J11: =IF(AND($D$2<1667,$D$3=1),'แบตเตอรีไฟฟ้า (ปี)'!B8,IF(AND($D$2<1667,$D$3=2),'แบตเตอรีไฟฟ้า (ปี)'!C8,IF(AND($D$2<1667,$D$3=3),'แบตเตอรีไฟฟ้า (ปี)'!D8,IF(AND($D$2<1667,$D$3=4),'แบตเตอรีไฟฟ้า (ปี)'!E8,IF(AND($D$2<1667,$D$3=5),'แบตเตอรีไฟฟ้า (ปี)'!F8,IF(AND($D$2<1667,$D$3=6),'แบตเตอรีไฟฟ้า (ปี)'!G8,IF(AND($D$2<1667,$D$3=7),'แบตเตอรีไฟฟ้า (ปี)'!H8,IF(AND($D$2<1667,$D$3=8),'แบตเตอรีไฟฟ้า (ปี)'!I8,IF(AND($D$2<1667,$D$3=9),'แบตเตอรีไฟฟ้า (ปี)'!I8,IF(AND($D$2<1667,$D$3=10),'แบตเตอรีไฟฟ้า (ปี)'!K8,IF(AND($D$2<1667,$D$3=11),'แบตเตอรีไฟฟ้า (ปี)'!I8,IF(AND($D$2<1667,$D$3=12),'แบตเตอรีไฟฟ้า (ปี)'!I8,IF(AND($D$2<1667,$D$3=13),'แบตเตอรีไฟฟ้า (ปี)'!I8,IF(AND($D$2<1667,$D$3=14),'แบตเตอรีไฟฟ้า (ปี)'!I8,IF(AND($D$2<1667,$D$3=15),'แบตเตอรีไฟฟ้า (ปี)'!I8,IF(AND($D$2<1667,$D$3=16),'แบตเตอรีไฟฟ้า (ปี)'!Q8,IF(AND($D$2<1667,$D$3=17),'แบตเตอรีไฟฟ้า (ปี)'!Q8,IF(AND($D$2<1667,$D$3=18),'แบตเตอรีไฟฟ้า (ปี)'!Q8,IF(AND($D$2<1667,$D$3=19),'แบตเตอรีไฟฟ้า (ปี)'!Q8,IF(AND($D$2<1667,$D$3=20),'แบตเตอรีไฟฟ้า (ปี)'!Q8,IF(AND($D$2>=1667,$D$4<170000),0,IF(AND($D$2>=1667,$D$4<340000),'แบตเตอรีรถไฟฟ้า(ระยะทาง)'!R8,IF(AND($D$2>=1667,$D$4<510000),'แบตเตอรีรถไฟฟ้า(ระยะทาง)'!AI8,))))))))))))))))))))))) -> 0 | K11: =IF(AND($D$2<1667,$D$3=1),'ค่าบำรุงรักษา(ปี)'!F8,IF(AND($D$2<1667,$D$3=2),'ค่าบำรุงรักษา(ปี)'!J8,IF(AND($D$2<1667,$D$3=3),'ค่าบำรุงรักษา(ปี)'!N8,IF(AND($D$2<1667,$D$3=4),'ค่าบำรุงรักษา(ปี)'!R8,IF(AND($D$2<1667,$D$3=5),'ค่าบำรุงรักษา(ปี)'!V8,IF(AND($D$2<1667,$D$3=6),'ค่าบำรุงรักษา(ปี)'!Z8,IF(AND($D$2<1667,$D$3=7),'ค่าบำรุงรักษา(ปี)'!AD8,IF(AND($D$2<1667,$D$3=8),'ค่าบำรุงรักษา(ปี)'!AH8,IF(AND($D$2<1667,$D$3=9),'ค่าบำรุงรักษา(ปี)'!AL8,IF(AND($D$2<1667,$D$3=10),'ค่าบำรุงรักษา(ปี)'!AP8,IF(AND($D$2<1667,$D$3=11),'ค่าบำรุงรักษา(ปี)'!AT8,IF(AND($D$2<1667,$D$3=12),'ค่าบำรุงรักษา(ปี)'!AX8,IF(AND($D$2<1667,$D$3=13),'ค่าบำรุงรักษา(ปี)'!BB8,IF(AND($D$2<1667,$D$3=14),'ค่าบำรุงรักษา(ปี)'!BF8,IF(AND($D$2<1667,$D$3=15),'ค่าบำรุงรักษา(ปี)'!BJ8,IF(AND($D$2<1667,$D$3=16),'ค่าบำรุงรักษา(ปี)'!BN8,IF(AND($D$2<1667,$D$3=17),'ค่าบำรุงรักษา(ปี)'!BR8,IF(AND($D$2<1667,$D$3=18),'ค่าบำรุงรักษา(ปี)'!BV8,IF(AND($D$2<1667,$D$3=19),'ค่าบำรุงรักษา(ปี)'!BZ8,IF(AND($D$2<1667,$D$3=20),'ค่าบำรุงรักษา(ปี)'!CD8,IF(AND($D$2>=1667,$D$4<30000),'ค่าบำรุงรักษา (ระยะทาง)'!G8,IF(AND($D$2>=1667,$D$4<40000),'ค่าบำรุงรักษา (ระยะทาง)'!I8,IF(AND($D$2>=1667,$D$4<50000),'ค่าบำรุงรักษา (ระยะทาง)'!K8,IF(AND($D$2>=1667,$D$4<60000),'ค่าบำรุงรักษา (ระยะทาง)'!M8,IF(AND($D$2>=1667,$D$4<70000),'ค่าบำรุงรักษา (ระยะทาง)'!O8,IF(AND($D$2>=1667,$D$4<80000),'ค่าบำรุงรักษา (ระยะทาง)'!Q8,IF(AND($D$2>=1667,$D$4<90000),'ค่าบำรุงรักษา (ระยะทาง)'!S8,IF(AND($D$2>=1667,$D$4<100000),'ค่าบำรุงรักษา (ระยะทาง)'!U8,IF(AND($D$2>=1667,$D$4<110000),'ค่าบำรุงรักษา (ระยะทาง)'!W8,IF(AND($D$2>=1667,$D$4<120000),'ค่าบำรุงรักษา (ระยะทาง)'!Y8,IF(AND($D$2>=1667,$D$4<130000),'ค่าบำรุงรักษา (ระยะทาง)'!AA8,IF(AND($D$2>=1667,$D$4<140000),'ค่าบำรุงรักษา (ระยะทาง)'!AC8,IF(AND($D$2>=1667,$D$4<150000),'ค่าบำรุงรักษา (ระยะทาง)'!AE8,IF(AND($D$2>=1667,$D$4<160000),'ค่าบำรุงรักษา (ระยะทาง)'!AG8,IF(AND($D$2>=1667,$D$4<170000),'ค่าบำรุงรักษา (ระยะทาง)'!AI8,IF(AND($D$2>=1667,$D$4<180000),'ค่าบำรุงรักษา (ระยะทาง)'!AK8,IF(AND($D$2>=1667,$D$4<190000),'ค่าบำรุงรักษา (ระยะทาง)'!AM8,IF(AND($D$2>=1667,$D$4<200000),'ค่าบำรุงรักษา (ระยะทาง)'!AO8,IF(AND($D$2>=1667,$D$4<210000),'ค่าบำรุงรักษา (ระยะทาง)'!AQ8,IF(AND($D$2>=1667,$D$4<220000),'ค่าบำรุงรักษา (ระยะทาง)'!AS8,IF(AND($D$2>=1667,$D$4<220000),'ค่าบำรุงรักษา (ระยะทาง)'!AU8,IF(AND($D$2>=1667,$D$4<240000),'ค่าบำรุงรักษา (ระยะทาง)'!AW8,IF(AND($D$2>=1667,$D$4<250000),'ค่าบำรุงรักษา (ระยะทาง)'!AY8,IF(AND($D$2>=1667,$D$4<260000),'ค่าบำรุงรักษา (ระยะทาง)'!BA8,IF(AND($D$2>=1667,$D$4<270000),'ค่าบำรุงรักษา (ระยะทาง)'!BC8,IF(AND($D$2>=1667,$D$4<280000),'ค่าบำรุงรักษา (ระยะทาง)'!BE8,IF(AND($D$2>=1667,$D$4<290000),'ค่าบำรุงรักษา (ระยะทาง)'!BG8,IF(AND($D$2>=1667,$D$4<300000),'ค่าบำรุงรักษา (ระยะทาง)'!BH6,IF(AND($D$2>=1667,$D$4<310000),'ค่าบำรุงรักษา (ระยะทาง)'!BK8,IF(AND($D$2>=1667,$D$4<320000),'ค่าบำรุงรักษา (ระยะทาง)'!BM8,IF(AND($D$2>=1667,$D$4<330000),'ค่าบำรุงรักษา (ระยะทาง)'!BO8,IF(AND($D$2>=1667,$D$4<340000),'ค่าบำรุงรักษา (ระยะทาง)'!BQ8,IF(AND($D$2>=1667,$D$4<350000),'ค่าบำรุงรักษา (ระยะทาง)'!BS8,IF(AND($D$2>=1667,$D$4<370000),'ค่าบำรุงรักษา (ระยะทาง)'!BW8,IF(AND($D$2>=1667,$D$4<380000),'ค่าบำรุงรักษา (ระยะทาง)'!BY8,IF(AND($D$2>=1667,$D$4<390000),'ค่าบำรุงรักษา (ระยะทาง)'!CA8,IF(AND($D$2>=1667,$D$4<400000),'ค่าบำรุงรักษา (ระยะทาง)'!CC8,IF(AND($D$2>=1667,$D$4<430000),'ค่าบำรุงรักษา (ระยะทาง)'!CI8,IF(AND($D$2>=1667,$D$4<440000),'ค่าบำรุงรักษา (ระยะทาง)'!CK8,IF(AND($D$2>=1667,$D$4<450000),'ค่าบำรุงรักษา (ระยะทาง)'!CM8,IF(AND($D$2>=1667,$D$4<460000),'ค่าบำรุงรักษา (ระยะทาง)'!CO8,IF(AND($D$2>=1667,$D$4<470000),'ค่าบำรุงรักษา (ระยะทาง)'!CQ8,IF(AND($D$2>=1667,$D$4<480000),'ค่าบำรุงรักษา (ระยะทาง)'!CS8,IF(AND($D$2>=1667,$D$4<490000),'ค่าบำรุงรักษา (ระยะทาง)'!CU8)))))))))))))))))))))))))))))))))))))))))))))))))))))))))))))))) -> 6300 | L11: =$D$4*$I$3/B11 -> 53880 | M11: =C11+E11+F11+G11+H11+I11+J11+K11+L11 -> 1288370.2
A12: Vios | B12: =ค่าพลังงาน!B11 -> 15.5 | C12: =ราคาเริ่มต้น!B9 -> 789000 | D12: =IF($D$3=1,ราคาเริ่มต้น!D9,IF($D$3=2,ราคาเริ่มต้น!E9,IF($D$3=3,ราคาเริ่มต้น!F9,IF($D$3=4,ราคาเริ่มต้น!G9,IF($D$3=5,ราคาเริ่มต้น!H9,IF($D$3=6,ราคาเริ่มต้น!I9,IF($D$3=7,ราคาเริ่มต้น!J9,IF($D$3=8,ราคาเริ่มต้น!K9,IF($D$3=9,ราคาเริ่มต้น!L9,IF($D$3=10,ราคาเริ่มต้น!M9,IF($D$3=11,ราคาเริ่มต้น!N9,IF($D$3=12,ราคาเริ่มต้น!O9,IF($D$3=13,ราคาเริ่มต้น!P9,IF($D$3=14,ราคาเริ่มต้น!Q9,IF($D$3=15,ราคาเริ่มต้น!R9,IF($D$3=16,ราคาเริ่มต้น!S9,IF($D$3=17,ราคาเริ่มต้น!T9,IF($D$3=18,ราคาเริ่มต้น!U9,IF($D$3=19,ราคาเริ่มต้น!V9,IF($D$3=20,ราคาเริ่มต้น!W9)))))))))))))))))))) -> 670650 | E12: =IF($D$3=1,ภาษีประจำปี!C9,IF($D$3=2,ภาษีประจำปี!E9,IF($D$3=3,ภาษีประจำปี!F9,IF($D$3=4,ภาษีประจำปี!I9,IF($D$3=5,ภาษีประจำปี!K9,IF($D$3=6,ภาษีประจำปี!M9,IF($D$3=7,ภาษีประจำปี!O9,IF($D$3=8,ภาษีประจำปี!Q9,IF($D$3=9,ภาษีประจำปี!S9,IF($D$3=10,ภาษีประจำปี!U9,IF($D$3=11,ภาษีประจำปี!W9,IF($D$3=12,ภาษีประจำปี!Y9,IF($D$3=13,ภาษีประจำปี!AA9,IF($D$3=14,ภาษีประจำปี!AC9,IF($D$3=15,ภาษีประจำปี!AE9,IF($D$3=16,ภาษีประจำปี!AG9,IF($D$3=17,ภาษีประจำปี!AI9,IF($D$3=18,ภาษีประจำปี!AK9,IF($D$3=19,ภาษีประจำปี!AM9,IF($D$3=20,ภาษีประจำปี!AO9)))))))))))))))))))) -> 1650 | F12: =IF($D$3=1,ประกันภัยบังคับ!B9,IF($D$3=2,ประกันภัยบังคับ!C9,IF($D$3=3,ประกันภัยบังคับ!D9,IF($D$3=4,ประกันภัยบังคับ!E9,IF($D$3=5,ประกันภัยบังคับ!F9,IF($D$3=6,ประกันภัยบังคับ!G9,IF($D$3=7,ประกันภัยบังคับ!H9,IF($D$3=8,ประกันภัยบังคับ!I9,IF($D$3=9,ประกันภัยบังคับ!J9,IF($D$3=10,ประกันภัยบังคับ!K9,IF($D$3=11,ประกันภัยบังคับ!L9,IF($D$3=12,ประกันภัยบังคับ!M9,IF($D$3=13,ประกันภัยบังคับ!N9,IF($D$3=14,ประกันภัยบังคับ!O9,IF($D$3=15,ประกันภัยบังคับ!P9,IF($D$3=16,ประกันภัยบังคับ!Q9,IF($D$3=17,ประกันภัยบังคับ!R9,IF($D$3=18,ประกันภัยบังคับ!S9,IF($D$3=19,ประกันภัยบังคับ!T9,IF($D$3=20,ประกันภัยบังคับ!U9)))))))))))))))))))) -> 645.21 | G12: =IF($D$3=1,ประกันภัยชั้น1!C9,IF($D$3=2,ประกันภัยชั้น1!E9,IF($D$3=3,ประกันภัยชั้น1!G9,IF($D$3=4,ประกันภัยชั้น1!I9,IF($D$3=5,ประกันภัยชั้น1!K9,IF($D$3=6,ประกันภัยชั้น1!M9,IF($D$3=7,ประกันภัยชั้น1!O9,IF($D$3=8,ประกันภัยชั้น1!Q9,IF($D$3=9,ประกันภัยชั้น1!S9,IF($D$3=10,ประกันภัยชั้น1!U9,IF($D$3=11,ประกันภัยชั้น1!W9,IF($D$3=12,ประกันภัยชั้น1!Y9,IF($D$3=13,ประกันภัยชั้น1!AA9,IF($D$3=14,ประกันภัยชั้น1!AC9,IF($D$3=15,ประกันภัยชั้น1!AE9,IF($D$3=16,ประกันภัยชั้น1!AG9,IF($D$3=17,ประกันภัยชั้น1!AI9,IF($D$3=18,ประกันภัยชั้น1!AK9,IF($D$3=19,ประกันภัยชั้น1!AM9,IF($D$3=20,ประกันภัยชั้น1!AO9)))))))))))))))))))) -> 16500 | H12: =IF(AND($D$2<1667,$D$3=1),'ยางรถ (ปี)'!B11,IF(AND($D$2<1667,$D$3=2),'ยางรถ (ปี)'!C11,IF(AND($D$2<1667,$D$3=3),'ยางรถ (ปี)'!D11,IF(AND($D$2<1667,$D$3=4),'ยางรถ (ปี)'!D11,IF(AND($D$2<1667,$D$3=5),'ยางรถ (ปี)'!D11,IF(AND($D$2<1667,$D$3=6),'ยางรถ (ปี)'!G11,IF(AND($D$2<1667,$D$3=7),'ยางรถ (ปี)'!G11,IF(AND($D$2<1667,$D$3=8),'ยางรถ (ปี)'!G11,IF(AND($D$2<1667,$D$3=9),'ยางรถ (ปี)'!J11,IF(AND($D$2<1667,$D$3=10),'ยางรถ (ปี)'!J11,IF(AND($D$2<1667,$D$3=11),'ยางรถ (ปี)'!J11,IF(AND($D$2<1667,$D$3=12),'ยางรถ (ปี)'!M11,IF(AND($D$2<1667,$D$3=13),'ยางรถ (ปี)'!M11,IF(AND($D$2<1667,$D$3=14),'ยางรถ (ปี)'!M11,IF(AND($D$2<1667,$D$3=15),'ยางรถ (ปี)'!P11,IF(AND($D$2<1667,$D$3=16),'ยางรถ (ปี)'!P11,IF(AND($D$2<1667,$D$3=17),'ยางรถ (ปี)'!P11,IF(AND($D$2<1667,$D$3=18),'ยางรถ (ปี)'!S11,IF(AND($D$2<1667,$D$3=19),'ยางรถ (ปี)'!S11,IF(AND($D$2<1667,$D$3=20),'ยางรถ (ปี)'!S11,IF(AND($D$2<1667,$D$3=21),'ยางรถ (ปี)'!V11,IF(AND($D$2>=1667,$D$4<50000),0,IF(AND($D$2>=1667, $D$4<100000),'ยางรถ(ระยะทาง)'!G9,IF(AND($D$2>=1667, $D$4<150000),'ยางรถ(ระยะทาง)'!M9,IF(AND($D$2>=1667, $D$4<200000),'ยางรถ(ระยะทาง)'!S9,IF(AND($D$2>=1667, $D$4<250000),'ยางรถ(ระยะทาง)'!Y9,IF(AND($D$2>=1667, $D$4<300000),'ยางรถ(ระยะทาง)'!AF9,IF(AND($D$2>=1667, $D$4<350000),'ยางรถ(ระยะทาง)'!AL9,IF(AND($D$2>=1667, $D$4<400000),'ยางรถ(ระยะทาง)'!AR9,IF(AND($D$2>=1667, $D$4<450000),'ยางรถ(ระยะทาง)'!AX9,IF(AND($D$2>=1667, $D$4<500000),'ยางรถ(ระยะทาง)'!BD9,IF(AND($D$2>=1667, $D$4<550000),'ยางรถ(ระยะทาง)'!BJ9,IF(AND($D$2>=1667, $D$4<600000),'ยางรถ(ระยะทาง)'!BL9,IF(AND($D$2>=1667, $D$4<650000),'ยางรถ(ระยะทาง)'!BN9,IF(AND($D$2>=1667, $D$4<700000),'ยางรถ(ระยะทาง)'!BP9,IF(AND($D$2>=1667, $D$4<750000),'ยางรถ(ระยะทาง)'!BR9,IF(AND($D$2>=1667, $D$4<800000),'ยางรถ(ระยะทาง)'!BV9))))))))))))))))))))))))))))))))))))) -> 0 | I12: =IF(AND($D$2<1667,$D$3=1),'แบตเตอร์รี่ (ปี)'!B9,IF(AND($D$2<1667,$D$3=2),'แบตเตอร์รี่ (ปี)'!C9,IF(AND($D$2<1667,$D$3=3),'แบตเตอร์รี่ (ปี)'!C9,IF(AND($D$2<1667,$D$3=4),'แบตเตอร์รี่ (ปี)'!E9,IF(AND($D$2<1667,$D$3=5),'แบตเตอร์รี่ (ปี)'!E9,IF(AND($D$2<1667,$D$3=6),'แบตเตอร์รี่ (ปี)'!G9,IF(AND($D$2<1667,$D$3=7),'แบตเตอร์รี่ (ปี)'!G9,IF(AND($D$2<1667,$D$3=8),'แบตเตอร์รี่ (ปี)'!I9,IF(AND($D$2<1667,$D$3=9),'แบตเตอร์รี่ (ปี)'!I9,IF(AND($D$2<1667,$D$3=10),'แบตเตอร์รี่ (ปี)'!K9,IF(AND($D$2<1667,$D$3=11),'แบตเตอร์รี่ (ปี)'!K9,IF(AND($D$2<1667,$D$3=12),'แบตเตอร์รี่ (ปี)'!M9,IF(AND($D$2<1667,$D$3=13),'แบตเตอร์รี่ (ปี)'!M9,IF(AND($D$2<1667,$D$3=14),'แบตเตอร์รี่ (ปี)'!O9,IF(AND($D$2<1667,$D$3=15),'แบตเตอร์รี่ (ปี)'!O9,IF(AND($D$2<1667,$D$3=16),'แบตเตอร์รี่ (ปี)'!Q9,IF(AND($D$2<1667,$D$3=17),'แบตเตอร์รี่ (ปี)'!Q9,IF(AND($D$2<1667,$D$3=18),'แบตเตอร์รี่ (ปี)'!S9,IF(AND($D$2<1667,$D$3=19),'แบตเตอร์รี่ (ปี)'!S9,IF(AND($D$2<1667,$D$3=20),'แบตเตอร์รี่ (ปี)'!U9,IF(AND($D$2>=1667,$D$4<40000),0,IF(AND($D$2>=1667,$D$4<80000),'แบตเตอรี(ระยะทาง) '!E9,IF(AND($D$2>=1667,$D$4<120000),'แบตเตอรี(ระยะทาง) '!I9,IF(AND($D$2>=1667,$D$4<160000),'แบตเตอรี(ระยะทาง) '!M9,IF(AND($D$2>=1667,$D$4<200000),'แบตเตอรี(ระยะทาง) '!Q9,IF(AND($D$2>=1667,$D$4<240000),'แบตเตอรี(ระยะทาง) '!E9,IF(AND($D$2>=1667,$D$4<280000),'แบตเตอรี(ระยะทาง) '!Y9,IF(AND($D$2>=1667,$D$4<320000),'แบตเตอรี(ระยะทาง) '!AC9,IF(AND($D$2>=1667,$D$4<360000),'แบตเตอรี(ระยะทาง) '!AG9,IF(AND($D$2>=1667,$D$4<400000),'แบตเตอรี(ระยะทาง) '!AK9,IF(AND($D$2>=1667,$D$4<440000),'แบตเตอรี(ระยะทาง) '!AO9,IF(AND($D$2>=1667,$D$4<480000),'แบตเตอรี(ระยะทาง) '!AS9,IF(AND($D$2>=1667,$D$4<50000),'แบตเตอรี(ระยะทาง) '!AW9,))))))))))))))))))))))))))))))))) -> 0 | J12: =IF(AND($D$2<1667,$D$3=1),'แบตเตอรีไฟฟ้า (ปี)'!B9,IF(AND($D$2<1667,$D$3=2),'แบตเตอรีไฟฟ้า (ปี)'!C9,IF(AND($D$2<1667,$D$3=3),'แบตเตอรีไฟฟ้า (ปี)'!D9,IF(AND($D$2<1667,$D$3=4),'แบตเตอรีไฟฟ้า (ปี)'!E9,IF(AND($D$2<1667,$D$3=5),'แบตเตอรีไฟฟ้า (ปี)'!F9,IF(AND($D$2<1667,$D$3=6),'แบตเตอรีไฟฟ้า (ปี)'!G9,IF(AND($D$2<1667,$D$3=7),'แบตเตอรีไฟฟ้า (ปี)'!H9,IF(AND($D$2<1667,$D$3=8),'แบตเตอรีไฟฟ้า (ปี)'!I9,IF(AND($D$2<1667,$D$3=9),'แบตเตอรีไฟฟ้า (ปี)'!I9,IF(AND($D$2<1667,$D$3=10),'แบตเตอรีไฟฟ้า (ปี)'!K9,IF(AND($D$2<1667,$D$3=11),'แบตเตอรีไฟฟ้า (ปี)'!I9,IF(AND($D$2<1667,$D$3=12),'แบตเตอรีไฟฟ้า (ปี)'!I9,IF(AND($D$2<1667,$D$3=13),'แบตเตอรีไฟฟ้า (ปี)'!I9,IF(AND($D$2<1667,$D$3=14),'แบตเตอรีไฟฟ้า (ปี)'!I9,IF(AND($D$2<1667,$D$3=15),'แบตเตอรีไฟฟ้า (ปี)'!I9,IF(AND($D$2<1667,$D$3=16),'แบตเตอรีไฟฟ้า (ปี)'!Q9,IF(AND($D$2<1667,$D$3=17),'แบตเตอรีไฟฟ้า (ปี)'!Q9,IF(AND($D$2<1667,$D$3=18),'แบตเตอรีไฟฟ้า (ปี)'!Q9,IF(AND($D$2<1667,$D$3=19),'แบตเตอรีไฟฟ้า (ปี)'!Q9,IF(AND($D$2<1667,$D$3=20),'แบตเตอรีไฟฟ้า (ปี)'!Q9,IF(AND($D$2>=1667,$D$4<170000),0,IF(AND($D$2>=1667,$D$4<340000),'แบตเตอรีรถไฟฟ้า(ระยะทาง)'!R9,IF(AND($D$2>=1667,$D$4<510000),'แบตเตอรีรถไฟฟ้า(ระยะทาง)'!AI9,))))))))))))))))))))))) -> 0 | K12: =IF(AND($D$2<1667,$D$3=1),'ค่าบำรุงรักษา(ปี)'!F9,IF(AND($D$2<1667,$D$3=2),'ค่าบำรุงรักษา(ปี)'!J9,IF(AND($D$2<1667,$D$3=3),'ค่าบำรุงรักษา(ปี)'!N9,IF(AND($D$2<1667,$D$3=4),'ค่าบำรุงรักษา(ปี)'!R9,IF(AND($D$2<1667,$D$3=5),'ค่าบำรุงรักษา(ปี)'!V9,IF(AND($D$2<1667,$D$3=6),'ค่าบำรุงรักษา(ปี)'!Z9,IF(AND($D$2<1667,$D$3=7),'ค่าบำรุงรักษา(ปี)'!AD9,IF(AND($D$2<1667,$D$3=8),'ค่าบำรุงรักษา(ปี)'!AH9,IF(AND($D$2<1667,$D$3=9),'ค่าบำรุงรักษา(ปี)'!AL9,IF(AND($D$2<1667,$D$3=10),'ค่าบำรุงรักษา(ปี)'!AP9,IF(AND($D$2<1667,$D$3=11),'ค่าบำรุงรักษา(ปี)'!AT9,IF(AND($D$2<1667,$D$3=12),'ค่าบำรุงรักษา(ปี)'!AX9,IF(AND($D$2<1667,$D$3=13),'ค่าบำรุงรักษา(ปี)'!BB9,IF(AND($D$2<1667,$D$3=14),'ค่าบำรุงรักษา(ปี)'!BF9,IF(AND($D$2<1667,$D$3=15),'ค่าบำรุงรักษา(ปี)'!BJ9,IF(AND($D$2<1667,$D$3=16),'ค่าบำรุงรักษา(ปี)'!BN9,IF(AND($D$2<1667,$D$3=17),'ค่าบำรุงรักษา(ปี)'!BR9,IF(AND($D$2<1667,$D$3=18),'ค่าบำรุงรักษา(ปี)'!BV9,IF(AND($D$2<1667,$D$3=19),'ค่าบำรุงรักษา(ปี)'!BZ9,IF(AND($D$2<1667,$D$3=20),'ค่าบำรุงรักษา(ปี)'!CD9,IF(AND($D$2>=1667,$D$4<30000),'ค่าบำรุงรักษา (ระยะทาง)'!G9,IF(AND($D$2>=1667,$D$4<40000),'ค่าบำรุงรักษา (ระยะทาง)'!I9,IF(AND($D$2>=1667,$D$4<50000),'ค่าบำรุงรักษา (ระยะทาง)'!K9,IF(AND($D$2>=1667,$D$4<60000),'ค่าบำรุงรักษา (ระยะทาง)'!M9,IF(AND($D$2>=1667,$D$4<70000),'ค่าบำรุงรักษา (ระยะทาง)'!O9,IF(AND($D$2>=1667,$D$4<80000),'ค่าบำรุงรักษา (ระยะทาง)'!Q9,IF(AND($D$2>=1667,$D$4<90000),'ค่าบำรุงรักษา (ระยะทาง)'!S9,IF(AND($D$2>=1667,$D$4<100000),'ค่าบำรุงรักษา (ระยะทาง)'!U9,IF(AND($D$2>=1667,$D$4<110000),'ค่าบำรุงรักษา (ระยะทาง)'!W9,IF(AND($D$2>=1667,$D$4<120000),'ค่าบำรุงรักษา (ระยะทาง)'!Y9,IF(AND($D$2>=1667,$D$4<130000),'ค่าบำรุงรักษา (ระยะทาง)'!AA9,IF(AND($D$2>=1667,$D$4<140000),'ค่าบำรุงรักษา (ระยะทาง)'!AC9,IF(AND($D$2>=1667,$D$4<150000),'ค่าบำรุงรักษา (ระยะทาง)'!AE9,IF(AND($D$2>=1667,$D$4<160000),'ค่าบำรุงรักษา (ระยะทาง)'!AG9,IF(AND($D$2>=1667,$D$4<170000),'ค่าบำรุงรักษา (ระยะทาง)'!AI9,IF(AND($D$2>=1667,$D$4<180000),'ค่าบำรุงรักษา (ระยะทาง)'!AK9,IF(AND($D$2>=1667,$D$4<190000),'ค่าบำรุงรักษา (ระยะทาง)'!AM9,IF(AND($D$2>=1667,$D$4<200000),'ค่าบำรุงรักษา (ระยะทาง)'!AO9,IF(AND($D$2>=1667,$D$4<210000),'ค่าบำรุงรักษา (ระยะทาง)'!AQ9,IF(AND($D$2>=1667,$D$4<220000),'ค่าบำรุงรักษา (ระยะทาง)'!AS9,IF(AND($D$2>=1667,$D$4<220000),'ค่าบำรุงรักษา (ระยะทาง)'!AU9,IF(AND($D$2>=1667,$D$4<240000),'ค่าบำรุงรักษา (ระยะทาง)'!AW9,IF(AND($D$2>=1667,$D$4<250000),'ค่าบำรุงรักษา (ระยะทาง)'!AY9,IF(AND($D$2>=1667,$D$4<260000),'ค่าบำรุงรักษา (ระยะทาง)'!BA9,IF(AND($D$2>=1667,$D$4<270000),'ค่าบำรุงรักษา (ระยะทาง)'!BC9,IF(AND($D$2>=1667,$D$4<280000),'ค่าบำรุงรักษา (ระยะทาง)'!BE9,IF(AND($D$2>=1667,$D$4<290000),'ค่าบำรุงรักษา (ระยะทาง)'!BG9,IF(AND($D$2>=1667,$D$4<300000),'ค่าบำรุงรักษา (ระยะทาง)'!BH7,IF(AND($D$2>=1667,$D$4<310000),'ค่าบำรุงรักษา (ระยะทาง)'!BK9,IF(AND($D$2>=1667,$D$4<320000),'ค่าบำรุงรักษา (ระยะทาง)'!BM9,IF(AND($D$2>=1667,$D$4<330000),'ค่าบำรุงรักษา (ระยะทาง)'!BO9,IF(AND($D$2>=1667,$D$4<340000),'ค่าบำรุงรักษา (ระยะทาง)'!BQ9,IF(AND($D$2>=1667,$D$4<350000),'ค่าบำรุงรักษา (ระยะทาง)'!BS9,IF(AND($D$2>=1667,$D$4<370000),'ค่าบำรุงรักษา (ระยะทาง)'!BW9,IF(AND($D$2>=1667,$D$4<380000),'ค่าบำรุงรักษา (ระยะทาง)'!BY9,IF(AND($D$2>=1667,$D$4<390000),'ค่าบำรุงรักษา (ระยะทาง)'!CA9,IF(AND($D$2>=1667,$D$4<400000),'ค่าบำรุงรักษา (ระยะทาง)'!CC9,IF(AND($D$2>=1667,$D$4<430000),'ค่าบำรุงรักษา (ระยะทาง)'!CI9,IF(AND($D$2>=1667,$D$4<440000),'ค่าบำรุงรักษา (ระยะทาง)'!CK9,IF(AND($D$2>=1667,$D$4<450000),'ค่าบำรุงรักษา (ระยะทาง)'!CM9,IF(AND($D$2>=1667,$D$4<460000),'ค่าบำรุงรักษา (ระยะทาง)'!CO9,IF(AND($D$2>=1667,$D$4<470000),'ค่าบำรุงรักษา (ระยะทาง)'!CQ9,IF(AND($D$2>=1667,$D$4<480000),'ค่าบำรุงรักษา (ระยะทาง)'!CS9,IF(AND($D$2>=1667,$D$4<490000),'ค่าบำรุงรักษา (ระยะทาง)'!CU9)))))))))))))))))))))))))))))))))))))))))))))))))))))))))))))))) -> 3700 | L12: =$D$4*$I$3/B12 -> 52141.935 | M12: =C12+(E12+F12+G12)+(H12+I12)+J12+K12+L12 -> 863637.15
